Workbook

Sheet Summary
A1: Dashboard
A2: Founder case vs market case — every tile is a formula; change the blue cells on Inputs and this page updates.
A4: =IF(ISNUMBER(Founder!B11),TEXT(Founder!B11,"0.0")&"×","n/a")&" | "&IF(ISNUMBER(Market!B11),TEXT(Market!B11,"0.0")&"×","n/a") -> 156.9× | 290.3× | C4: =Founder!B12&" | "&Market!B12 -> 1 | 1 | E4: =Founder!B53&" | "&Market!B53 -> 16 | 9 | G4: =TEXT(Founder!B54,"#,##0")&" | "&TEXT(Market!B54,"#,##0") -> 138,670 | 87,833 | I4: =TEXT(Founder!F51,"#,##0")&" | "&TEXT(Market!F51,"#,##0") -> 73,105 | 135,244 | K4: =IF(Market!B4*Market!B10>0,3*Market!B7/(Market!B10/Market!B3),0) -> 28.677863
A5: LTV / CAC (cash) — founder | market | C5: Payback, months — founder | market | E5: Break-even month — founder | market | G5: Peak capital need — founder | market | I5: Revenue month 36 — founder | market | K5: Revenue per customer needed for LTV/CAC = 3 (market)
A7: Metric | B7: Founder | C7: Market | D7: Pessimistic | E7: Optimistic
A8: Blended CAC | B8: =Founder!B7 -> 175 | C8: =Market!B7 -> 175 | D8: =Pessimistic!B7 -> 300 | E8: =Optimistic!B7 -> 50
A9: LTV (lifetime gross-margin contribution, 60-mo cap) | B9: =Founder!B10 -> 27460.205 | C9: =Market!B10 -> 50801.379 | D9: =Pessimistic!B10 -> 16276.552 | E9: =Optimistic!B10 -> 151507.86
A10: LTV / CAC (cash) | B10: =Founder!B11 -> 156.91546 | C10: =Market!B11 -> 290.29359 | D10: =Pessimistic!B11 -> 54.255172 | E10: =Optimistic!B11 -> 3030.1571
A11: Payback (months, cumulative) | B11: =Founder!B12 -> 1 | C11: =Market!B12 -> 1 | D11: =Pessimistic!B12 -> 1 | E11: =Optimistic!B12 -> 1
A12: Gross margin | B12: =Founder!B4 -> 0.525 | C12: =Market!B4 -> 0.525 | D12: =Pessimistic!B4 -> 0.4 | E12: =Optimistic!B4 -> 0.65
A13: Break-even month | B13: =Founder!B53 -> 16 | C13: =Market!B53 -> 9 | D13: =Pessimistic!B53 -> none | E13: =Optimistic!B53 -> 4
A14: Peak capital need | B14: =Founder!B54 -> 138670.09 | C14: =Market!B54 -> 87833.466 | D14: =Pessimistic!B54 -> 592897.95 | E14: =Optimistic!B54 -> 22733.493
A15: Revenue month 12 | B15: =Founder!F27 -> 25614.27 | C15: =Market!F27 -> 47386.399 | D15: =Pessimistic!F27 -> 14435.21 | E15: =Optimistic!F27 -> 104011.3
A16: Revenue month 24 | B16: =Founder!F39 -> 52266.61 | C16: =Market!F39 -> 96693.229 | D16: =Pessimistic!F39 -> 26352.156 | E16: =Optimistic!F39 -> 240484.06
A17: Revenue month 36 | B17: =Founder!F51 -> 73104.622 | C17: =Market!F51 -> 135243.55 | D17: =Pessimistic!F51 -> 33473.406 | E17: =Optimistic!F51 -> 379667.76
A18: Customers month 36 | B18: =Founder!D51 -> 42.46659 | C18: =Market!D51 -> 42.46659 | D18: =Pessimistic!D51 -> 18.093733 | E18: =Optimistic!D51 -> 75.614427
A21: Month | B21: Rev Founder | C21: Rev Market | D21: Rev Pessimistic | E21: Rev Optimistic | F21: Cash Founder | G21: Cash Market | H21: Cash Pessimistic | I21: Cash Optimistic | J21: Units Founder | K21: Units Market | L21: Units Pessimistic | M21: Units Optimistic
A22: 1 | B22: =Founder!F16 -> 0 | C22: =Market!F16 -> 0 | D22: =Pessimistic!F16 -> 0 | E22: =Optimistic!F16 -> 0 | F22: =Founder!K16 -> -17094.129 | G22: =Market!K16 -> -17094.129 | H22: =Pessimistic!K16 -> -24080.682 | I22: =Optimistic!K16 -> -10040.341 | J22: =Founder!D16 -> 0 | K22: =Market!D16 -> 0 | L22: =Pessimistic!D16 -> 0 | M22: =Optimistic!D16 -> 0
A23: 2 | B23: =Founder!F17 -> 806.82426 | C23: =Market!F17 -> 1492.6249 | D23: =Pessimistic!F17 -> 497.54163 | E23: =Optimistic!F17 -> 2985.2498 | F23: =Founder!K17 -> -33845.547 | G23: =Market!K17 -> -33485.501 | H23: =Pessimistic!K17 -> -48031.666 | I23: =Optimistic!K17 -> -18174.929 | J23: =Founder!D17 -> 0.53788284 | K23: =Market!D17 -> 0.53788284 | L23: =Pessimistic!D17 -> 0.26894142 | M23: =Optimistic!D17 -> 0.80682426
A24: 3 | B24: =Founder!F18 -> 2290.4457 | C24: =Market!F18 -> 4237.3246 | D24: =Pessimistic!F18 -> 1401.6449 | E24: =Optimistic!F18 -> 8540.1456 | F24: =Founder!K18 -> -49898.933 | G24: =Market!K18 -> -48516.777 | H24: =Pessimistic!K18 -> -71690.325 | I24: =Optimistic!K18 -> -22733.493 | J24: =Founder!D18 -> 1.5217464 | K24: =Market!D18 -> 1.5217464 | L24: =Pessimistic!D18 -> 0.75764588 | M24: =Optimistic!D18 -> 2.2923014
A25: 4 | B25: =Founder!F19 -> 4437.1254 | C25: =Market!F19 -> 8208.682 | D25: =Pessimistic!F19 -> 2695.2342 | E25: =Optimistic!F19 -> 16668.902 | F25: =Founder!K19 -> -64877.721 | G25: =Market!K19 -> -61515.497 | H25: =Pessimistic!K19 -> -94876.471 | I25: =Optimistic!K19 -> -22030.827 | J25: =Founder!D19 -> 2.9382111 | K25: =Market!D19 -> 2.9382111 | L25: =Pessimistic!D19 -> 1.4568833 | M25: =Optimistic!D19 -> 4.4442157
A26: 5 | B26: =Founder!F20 -> 6989.443 | C26: =Market!F20 -> 12930.47 | D26: =Pessimistic!F20 -> 4211.5089 | E26: =Optimistic!F20 -> 26473.086 | F26: =Founder!K20 -> -78541.665 | G26: =Market!K20 -> -72060.402 | H26: =Pessimistic!K20 -> -117477.64 | I26: =Optimistic!K20 -> -14966.207 | J26: =Founder!D20 -> 4.6116589 | K26: =Market!D20 -> 4.6116589 | L26: =Pessimistic!D20 -> 2.2764913 | M26: =Optimistic!D20 -> 7.0066111
A27: 6 | B27: =Founder!F21 -> 9705.2797 | C27: =Market!F21 -> 17954.767 | D27: =Pessimistic!F21 -> 5796.8877 | E27: =Optimistic!F21 -> 37090.075 | F27: =Founder!K21 -> -90790.098 | G27: =Market!K21 -> -79977.854 | H27: =Pessimistic!K21 -> -139453.49 | I27: =Optimistic!K21 -> -1004.96 | J27: =Founder!D21 -> 6.3784574 | K27: =Market!D21 -> 6.3784574 | L27: =Pessimistic!D21 -> 3.1334528 | M27: =Optimistic!D21 -> 9.7382145
A28: 7 | B28: =Founder!F22 -> 12454.304 | C28: =Market!F22 -> 23040.462 | D28: =Pessimistic!F22 -> 7370.1439 | E28: =Optimistic!F22 -> 48051.256 | F28: =Founder!K22 -> -101599.25 | G28: =Market!K22 -> -85229.269 | H28: =Pessimistic!K22 -> -160803.42 | I28: =Optimistic!K22 -> 20079.36 | J28: =Founder!D22 -> 8.1511313 | K28: =Market!D22 -> 8.1511313 | L28: =Pessimistic!D22 -> 3.9838616 | M28: =Optimistic!D22 -> 12.508968
A29: 8 | B29: =Founder!F23 -> 15181.403 | C29: =Market!F23 -> 28085.595 | D29: =Pessimistic!F23 -> 8898.2161 | E29: =Optimistic!F23 -> 59155.769 | F29: =Founder!K23 -> -110978.14 | G29: =Market!K23 -> -87833.466 | H29: =Pessimistic!K23 -> -181543.39 | I29: =Optimistic!K23 -> 48380.981 | J29: =Founder!D23 -> 9.8932116 | K29: =Market!D23 -> 9.8932116 | L29: =Pessimistic!D23 -> 4.8098465 | M29: =Optimistic!D23 -> 15.263728
A30: 9 | B30: =Founder!F24 -> 17865.803 | C30: =Market!F24 -> 33051.735 | D30: =Pessimistic!F24 -> 10369.917 | E30: =Optimistic!F24 -> 70325.338 | F30: =Founder!K24 -> -118948.28 | G30: =Market!K24 -> -87830.986 | H30: =Pessimistic!K24 -> -201695.15 | I30: =Optimistic!K24 -> 83942.588 | J30: =Founder!D24 -> 11.59147 | K30: =Market!D24 -> 11.59147 | L30: =Pessimistic!D24 -> 5.6053604 | M30: =Optimistic!D24 -> 17.981563
A31: 10 | B31: =Founder!F25 -> 20500.394 | C31: =Market!F25 -> 37925.728 | D31: =Pessimistic!F25 -> 11782.695 | E31: =Optimistic!F25 -> 81530.559 | F31: =Founder!K25 -> -125535.45 | G31: =Market!K25 -> -85269.861 | H31: =Pessimistic!K25 -> -221281.98 | I31: =Optimistic!K25 -> 126787.5 | J31: =Founder!D25 -> 13.241904 | K31: =Market!D25 -> 13.241904 | L31: =Pessimistic!D25 -> 6.3690242 | M31: =Optimistic!D25 -> 20.655162
A32: 11 | B32: =Founder!F26 -> 23083.23 | C32: =Market!F26 -> 42703.975 | D32: =Pessimistic!F26 -> 13137.201 | E32: =Optimistic!F26 -> 92760.547 | F32: =Founder!K26 -> -130766.72 | G32: =Market!K26 -> -80200.231 | H32: =Pessimistic!K26 -> -240327.06 | I32: =Optimistic!K26 -> 176931.88 | J32: =Founder!D26 -> 14.843976 | K32: =Market!D26 -> 14.843976 | L32: =Pessimistic!D26 -> 7.1011898 | M32: =Optimistic!D26 -> 23.282363
A33: 12 | B33: =Founder!F27 -> 25614.27 | C33: =Market!F27 -> 47386.399 | D33: =Pessimistic!F27 -> 14435.21 | E33: =Optimistic!F27 -> 104011.3 | F33: =Founder!K27 -> -134669.21 | G33: =Market!K27 -> -72672.356 | H33: =Pessimistic!K27 -> -258852.96 | I33: =Optimistic!K27 -> 234389.23 | J33: =Founder!D27 -> 16.39841 | K33: =Market!D27 -> 16.39841 | L33: =Pessimistic!D27 -> 7.8028164 | M33: =Optimistic!D27 -> 25.86291
... A57: 36 | B57: =Founder!F51 -> 73104.622 | C57: =Market!F51 -> 135243.55 | D57: =Pessimistic!F51 -> 33473.406 | E57: =Optimistic!F51 -> 379667.76 | F57: =Founder!K51 -> 107727.87 | G57: =Market!K51 -> 729702.22 | H57: =Pessimistic!K51 -> -592897.95 | I57: =Optimistic!K51 -> 3839000.2 | J57: =Founder!D51 -> 42.46659 | K57: =Market!D51 -> 42.46659 | L57: =Pessimistic!D51 -> 18.093733 | M57: =Optimistic!D51 -> 75.614427

Sheet Growth
A1: Growth funnel (documentation of where the capacity number came from)
A3: Motion: founder_led · ramp 50% at month 2 · lag 1 mo
A5: Funnel step | B5: Value | C5: Source
A6: 30-min calls / month | B6: 4–10 | C6: founder content + 7-day email course, estimate
A7: → signed retainer | B7: 25–35 % | C7: conv.demo.close.smb (secondary)
A9: The resulting capacity is the blue 'New customers per month at full capacity' input. Edit it there.

Sheet Inputs
A1: Assumptions — founder vs market
A2: Revenue unit: subscription. Blue cells are inputs. Founder = the founder's number; Market = midpoint of the benchmark range (low/high feed the pessimistic and optimistic cases).
A4: Assumption | B4: Founder | C4: Market (mid) | D4: Market low | E4: Market high | F4: Founder status | G4: Market source
A5: Price | B5: 1500 | C5: =AVERAGE(D5,E5) -> 2775 | D5: 1850 | E5: 3700 | F5: founder_stated | G5: published price €1 500/mo (magicpost.in review, Jan 2026); market: agency retainer mid tier 12–16 posts $2 000–4 000/mo (Windmill Growth via magicpost.in ghostwriting-rates, Sep 2026) × 0.92 EUR/USD
A6: Gross margin | B6: =AVERAGE(D6,E6) -> 0.525 | C6: =AVERAGE(D6,E6) -> 0.525 | D6: 0.4 | E6: 0.65 | F6: benchmarked · filled_from_market | G6: margin.services — agency delivery margin (secondary, unverified entry)
A7: Monthly churn | B7: =AVERAGE(D7,E7) -> 0.03 | C7: =AVERAGE(D7,E7) -> 0.03 | D7: 0.018 | E7: 0.042 | F7: benchmarked · filled_from_market | G7: churn.agency.project.2025 — retainer agencies: >20 %/yr is a red flag; 20–40 %/yr → 1−(1−a)^(1/12) = 1.8–4.2 %/mo (secondary)
A8: Expansion | B8: =AVERAGE(D8,E8) -> 0.01 | C8: =AVERAGE(D8,E8) -> 0.01 | D8: 0 | E8: 0.02 | F8: benchmarked · filled_from_market | G8: upsell from €1 500 management to €2 500 lead-gen tier; expansion.seat_b2b lower half (secondary, unverified)
A9: New customers per month | B9: =AVERAGE(D9,E9) -> 2 | C9: =AVERAGE(D9,E9) -> 2 | D9: 1 | E9: 3 | F9: benchmarked · filled_from_market | G9: capacity.founder_led: inbound from founder content + 30-min calls, one part-time seller; 1–3 signed retainers/mo (secondary)
A10: Cost per fte per month | B10: =AVERAGE(D10,E10) -> 4250 | C10: =AVERAGE(D10,E10) -> 4250 | D10: 2500 | E10: 6000 | F10: benchmarked · filled_from_market | G10: fte.cost.e_eu_latam / fte.cost.region — remote team of ~4 FTE across Europe (secondary, unverified)
A11: Cost to acquire | B11: =AVERAGE(D11,E11) -> 175 | C11: =AVERAGE(D11,E11) -> 175 | D11: 50 | E11: 300 | F11: benchmarked · filled_from_market | G11: денежные расходы на одного подписанного клиента при продажах через контент основателя: Sales Navigator, инструменты, мероприятия; оценка аналитика по аналогии с cac.microsaas.organic.2025 (0–50 $ без учёта времени) плюс инструменты; время команды — в зарплатах
A13: Scalars (same in every case)
A14: Team size (FTE) | B14: 4
A15: Fixed monthly overhead (content, licences, infra floor) | B15: 0
A16: Upfront investment before first revenue | B16: 0
A17: Free months per new customer (long trial) | B17: 0
A18: Founder time per new customer, value of unpaid hours (not cash; ratios only) | B18: 0
A19: Starting paying customers (post-revenue only, measured) | B19: 0
A20: Starting monthly revenue (post-revenue only, measured) | B20: 0
A21: Ramp: month at 50% capacity | B21: 2
A22: Ramp: steepness k (0 = no ramp) | B22: 1
A23: Sales-cycle lag (months) | B23: 1
A25: Acquisition channels — the founder's CAC is the volume-weighted average of this table
A26: Channel | B26: Customers / month | C26: Channel CAC | D26: Effective CAC
A27: (none — CAC from the assumption row) | D27: =C27 -> 0

Sheet Founder
A1: Founder case
A3: Revenue per customer-month (ARPU₀) | B3: =Inputs!B5 -> 1500
A4: Gross margin | B4: =Inputs!B6 -> 0.525
A5: Monthly churn | B5: =Inputs!B7 -> 0.03
A6: Monthly expansion | B6: =Inputs!B8 -> 0.01
A7: Blended CAC | B7: =Inputs!B11 -> 175
A8: Fixed burn / month | B8: =Inputs!B14*Inputs!B10+Inputs!B15 -> 17000
A9: New customers / month at full capacity | B9: =Inputs!B9 -> 2
A10: LTV (lifetime contribution, 60-mo cap) | B10: =B3*B4*(1-B5)^Inputs!B17*IF(ABS(1-(1-B5)*(1+B6))<0.000001,MAX(0,60-Inputs!B17),(1-((1-B5)*(1+B6))^MAX(0,60-Inputs!B17))/(1-(1-B5)*(1+B6))) -> 27460.205
A11: LTV / CAC (cash) | B11: =IF(B7>0,B10/B7,"n/a") -> 156.91546
A12: Payback (months, cumulative; "none" = not within 60) | B12: =IF(B3*B4<=0,"none",IF(B7<=0,1+Inputs!B17,IF((1-B5)*(1+B6)<=0,IF(B7<=B3*B4*(1-B5)^Inputs!B17,1+Inputs!B17,"none"),IF(ABS(1-(1-B5)*(1+B6))<0.000001,IF(B7/(B3*B4*(1-B5)^Inputs!B17)<=60-Inputs!B17,ROUNDUP(B7/(B3*B4*(1-B5)^Inputs!B17),0)+Inputs!B17,"none"),IF(1-B7*(1-(1-B5)*(1+B6))/(B3*B4*(1-B5)^Inputs!B17)<=0,"none",IF(ROUNDUP(LN(1-B7*(1-(1-B5)*(1+B6))/(B3*B4*(1-B5)^Inputs!B17))/LN((1-B5)*(1+B6)),0)<=60-Inputs!B17,ROUNDUP(LN(1-B7*(1-(1-B5)*(1+B6))/(B3*B4*(1-B5)^Inputs!B17))/LN((1-B5)*(1+B6)),0)+Inputs!B17,"none")))))) -> 1
A15: Month | B15: Ramp | C15: New customers (arrivals) | D15: Paying customers | E15: ARPU (derived) | F15: Revenue | G15: Gross profit | H15: Acquisition spend | I15: Fixed burn | J15: Net cash flow | K15: Cumulative cash | L15: Lowest net from here on
A16: 1 | B16: =IF(Inputs!B22=0,1,1/(1+EXP(-Inputs!B22*(A16-Inputs!B21)))) -> 0.26894142 | C16: =IF(A16-Inputs!B23<1,0,$B$9*IF(Inputs!B22=0,1,1/(1+EXP(-Inputs!B22*(A16-Inputs!B23-Inputs!B21))))) -> 0 | D16: =Inputs!B19*(1-$B$5)+IF(A16-Inputs!B17<1,0,OFFSET(C16,-Inputs!B17,0)*(1-$B$5)^Inputs!B17) -> 0 | E16: =IF(D16>0,F16/D16,0) -> 0 | F16: =Inputs!B20*(1-$B$5)*(1+$B$6)+IF(A16-Inputs!B17<1,0,OFFSET(C16,-Inputs!B17,0)*(1-$B$5)^Inputs!B17)*$B$3 -> 0 | G16: =F16*$B$4 -> 0 | H16: =$B$9*B16*$B$7 -> 94.129497 | I16: =$B$8 -> 17000 | J16: =G16-H16-I16 -> -17094.129 | K16: =J16-Inputs!B16 -> -17094.129 | L16: =MIN(J16:J51) -> -17094.129
A17: 2 | B17: =IF(Inputs!B22=0,1,1/(1+EXP(-Inputs!B22*(A17-Inputs!B21)))) -> 0.5 | C17: =IF(A17-Inputs!B23<1,0,$B$9*IF(Inputs!B22=0,1,1/(1+EXP(-Inputs!B22*(A17-Inputs!B23-Inputs!B21))))) -> 0.53788284 | D17: =D16*(1-$B$5)+IF(A17-Inputs!B17<1,0,OFFSET(C17,-Inputs!B17,0)*(1-$B$5)^Inputs!B17) -> 0.53788284 | E17: =IF(D17>0,F17/D17,0) -> 1500 | F17: =F16*(1-$B$5)*(1+$B$6)+IF(A17-Inputs!B17<1,0,OFFSET(C17,-Inputs!B17,0)*(1-$B$5)^Inputs!B17)*$B$3 -> 806.82426 | G17: =F17*$B$4 -> 423.58274 | H17: =$B$9*B17*$B$7 -> 175 | I17: =$B$8 -> 17000 | J17: =G17-H17-I17 -> -16751.417 | K17: =K16+J17 -> -33845.547 | L17: =MIN(J17:J51) -> -16751.417
A18: 3 | B18: =IF(Inputs!B22=0,1,1/(1+EXP(-Inputs!B22*(A18-Inputs!B21)))) -> 0.73105858 | C18: =IF(A18-Inputs!B23<1,0,$B$9*IF(Inputs!B22=0,1,1/(1+EXP(-Inputs!B22*(A18-Inputs!B23-Inputs!B21))))) -> 1 | D18: =D17*(1-$B$5)+IF(A18-Inputs!B17<1,0,OFFSET(C18,-Inputs!B17,0)*(1-$B$5)^Inputs!B17) -> 1.5217464 | E18: =IF(D18>0,F18/D18,0) -> 1505.1429 | F18: =F17*(1-$B$5)*(1+$B$6)+IF(A18-Inputs!B17<1,0,OFFSET(C18,-Inputs!B17,0)*(1-$B$5)^Inputs!B17)*$B$3 -> 2290.4457 | G18: =F18*$B$4 -> 1202.484 | H18: =$B$9*B18*$B$7 -> 255.8705 | I18: =$B$8 -> 17000 | J18: =G18-H18-I18 -> -16053.386 | K18: =K17+J18 -> -49898.933 | L18: =MIN(J18:J51) -> -16053.386
A19: 4 | B19: =IF(Inputs!B22=0,1,1/(1+EXP(-Inputs!B22*(A19-Inputs!B21)))) -> 0.88079708 | C19: =IF(A19-Inputs!B23<1,0,$B$9*IF(Inputs!B22=0,1,1/(1+EXP(-Inputs!B22*(A19-Inputs!B23-Inputs!B21))))) -> 1.4621172 | D19: =D18*(1-$B$5)+IF(A19-Inputs!B17<1,0,OFFSET(C19,-Inputs!B17,0)*(1-$B$5)^Inputs!B17) -> 2.9382111 | E19: =IF(D19>0,F19/D19,0) -> 1510.1452 | F19: =F18*(1-$B$5)*(1+$B$6)+IF(A19-Inputs!B17<1,0,OFFSET(C19,-Inputs!B17,0)*(1-$B$5)^Inputs!B17)*$B$3 -> 4437.1254 | G19: =F19*$B$4 -> 2329.4908 | H19: =$B$9*B19*$B$7 -> 308.27898 | I19: =$B$8 -> 17000 | J19: =G19-H19-I19 -> -14978.788 | K19: =K18+J19 -> -64877.721 | L19: =MIN(J19:J51) -> -14978.788
A20: 5 | B20: =IF(Inputs!B22=0,1,1/(1+EXP(-Inputs!B22*(A20-Inputs!B21)))) -> 0.95257413 | C20: =IF(A20-Inputs!B23<1,0,$B$9*IF(Inputs!B22=0,1,1/(1+EXP(-Inputs!B22*(A20-Inputs!B23-Inputs!B21))))) -> 1.7615942 | D20: =D19*(1-$B$5)+IF(A20-Inputs!B17<1,0,OFFSET(C20,-Inputs!B17,0)*(1-$B$5)^Inputs!B17) -> 4.6116589 | E20: =IF(D20>0,F20/D20,0) -> 1515.6028 | F20: =F19*(1-$B$5)*(1+$B$6)+IF(A20-Inputs!B17<1,0,OFFSET(C20,-Inputs!B17,0)*(1-$B$5)^Inputs!B17)*$B$3 -> 6989.443 | G20: =F20*$B$4 -> 3669.4576 | H20: =$B$9*B20*$B$7 -> 333.40094 | I20: =$B$8 -> 17000 | J20: =G20-H20-I20 -> -13663.943 | K20: =K19+J20 -> -78541.665 | L20: =MIN(J20:J51) -> -13663.943
A21: 6 | B21: =IF(Inputs!B22=0,1,1/(1+EXP(-Inputs!B22*(A21-Inputs!B21)))) -> 0.98201379 | C21: =IF(A21-Inputs!B23<1,0,$B$9*IF(Inputs!B22=0,1,1/(1+EXP(-Inputs!B22*(A21-Inputs!B23-Inputs!B21))))) -> 1.9051483 | D21: =D20*(1-$B$5)+IF(A21-Inputs!B17<1,0,OFFSET(C21,-Inputs!B17,0)*(1-$B$5)^Inputs!B17) -> 6.3784574 | E21: =IF(D21>0,F21/D21,0) -> 1521.5716 | F21: =F20*(1-$B$5)*(1+$B$6)+IF(A21-Inputs!B17<1,0,OFFSET(C21,-Inputs!B17,0)*(1-$B$5)^Inputs!B17)*$B$3 -> 9705.2797 | G21: =F21*$B$4 -> 5095.2718 | H21: =$B$9*B21*$B$7 -> 343.70483 | I21: =$B$8 -> 17000 | J21: =G21-H21-I21 -> -12248.433 | K21: =K20+J21 -> -90790.098 | L21: =MIN(J21:J51) -> -12248.433
A22: 7 | B22: =IF(Inputs!B22=0,1,1/(1+EXP(-Inputs!B22*(A22-Inputs!B21)))) -> 0.99330715 | C22: =IF(A22-Inputs!B23<1,0,$B$9*IF(Inputs!B22=0,1,1/(1+EXP(-Inputs!B22*(A22-Inputs!B23-Inputs!B21))))) -> 1.9640276 | D22: =D21*(1-$B$5)+IF(A22-Inputs!B17<1,0,OFFSET(C22,-Inputs!B17,0)*(1-$B$5)^Inputs!B17) -> 8.1511313 | E22: =IF(D22>0,F22/D22,0) -> 1527.9234 | F22: =F21*(1-$B$5)*(1+$B$6)+IF(A22-Inputs!B17<1,0,OFFSET(C22,-Inputs!B17,0)*(1-$B$5)^Inputs!B17)*$B$3 -> 12454.304 | G22: =F22*$B$4 -> 6538.5095 | H22: =$B$9*B22*$B$7 -> 347.6575 | I22: =$B$8 -> 17000 | J22: =G22-H22-I22 -> -10809.148 | K22: =K21+J22 -> -101599.25 | L22: =MIN(J22:J51) -> -10809.148
A23: 8 | B23: =IF(Inputs!B22=0,1,1/(1+EXP(-Inputs!B22*(A23-Inputs!B21)))) -> 0.99752738 | C23: =IF(A23-Inputs!B23<1,0,$B$9*IF(Inputs!B22=0,1,1/(1+EXP(-Inputs!B22*(A23-Inputs!B23-Inputs!B21))))) -> 1.9866143 | D23: =D22*(1-$B$5)+IF(A23-Inputs!B17<1,0,OFFSET(C23,-Inputs!B17,0)*(1-$B$5)^Inputs!B17) -> 9.8932116 | E23: =IF(D23>0,F23/D23,0) -> 1534.5273 | F23: =F22*(1-$B$5)*(1+$B$6)+IF(A23-Inputs!B17<1,0,OFFSET(C23,-Inputs!B17,0)*(1-$B$5)^Inputs!B17)*$B$3 -> 15181.403 | G23: =F23*$B$4 -> 7970.2366 | H23: =$B$9*B23*$B$7 -> 349.13458 | I23: =$B$8 -> 17000 | J23: =G23-H23-I23 -> -9378.898 | K23: =K22+J23 -> -110978.14 | L23: =MIN(J23:J51) -> -9378.898
A24: 9 | B24: =IF(Inputs!B22=0,1,1/(1+EXP(-Inputs!B22*(A24-Inputs!B21)))) -> 0.99908895 | C24: =IF(A24-Inputs!B23<1,0,$B$9*IF(Inputs!B22=0,1,1/(1+EXP(-Inputs!B22*(A24-Inputs!B23-Inputs!B21))))) -> 1.9950548 | D24: =D23*(1-$B$5)+IF(A24-Inputs!B17<1,0,OFFSET(C24,-Inputs!B17,0)*(1-$B$5)^Inputs!B17) -> 11.59147 | E24: =IF(D24>0,F24/D24,0) -> 1541.2888 | F24: =F23*(1-$B$5)*(1+$B$6)+IF(A24-Inputs!B17<1,0,OFFSET(C24,-Inputs!B17,0)*(1-$B$5)^Inputs!B17)*$B$3 -> 17865.803 | G24: =F24*$B$4 -> 9379.5464 | H24: =$B$9*B24*$B$7 -> 349.68113 | I24: =$B$8 -> 17000 | J24: =G24-H24-I24 -> -7970.1348 | K24: =K23+J24 -> -118948.28 | L24: =MIN(J24:J51) -> -7970.1348
A25: 10 | B25: =IF(Inputs!B22=0,1,1/(1+EXP(-Inputs!B22*(A25-Inputs!B21)))) -> 0.99966465 | C25: =IF(A25-Inputs!B23<1,0,$B$9*IF(Inputs!B22=0,1,1/(1+EXP(-Inputs!B22*(A25-Inputs!B23-Inputs!B21))))) -> 1.9981779 | D25: =D24*(1-$B$5)+IF(A25-Inputs!B17<1,0,OFFSET(C25,-Inputs!B17,0)*(1-$B$5)^Inputs!B17) -> 13.241904 | E25: =IF(D25>0,F25/D25,0) -> 1548.1455 | F25: =F24*(1-$B$5)*(1+$B$6)+IF(A25-Inputs!B17<1,0,OFFSET(C25,-Inputs!B17,0)*(1-$B$5)^Inputs!B17)*$B$3 -> 20500.394 | G25: =F25*$B$4 -> 10762.707 | H25: =$B$9*B25*$B$7 -> 349.88263 | I25: =$B$8 -> 17000 | J25: =G25-H25-I25 -> -6587.176 | K25: =K24+J25 -> -125535.45 | L25: =MIN(J25:J51) -> -6587.176
A26: 11 | B26: =IF(Inputs!B22=0,1,1/(1+EXP(-Inputs!B22*(A26-Inputs!B21)))) -> 0.99987661 | C26: =IF(A26-Inputs!B23<1,0,$B$9*IF(Inputs!B22=0,1,1/(1+EXP(-Inputs!B22*(A26-Inputs!B23-Inputs!B21))))) -> 1.9993293 | D26: =D25*(1-$B$5)+IF(A26-Inputs!B17<1,0,OFFSET(C26,-Inputs!B17,0)*(1-$B$5)^Inputs!B17) -> 14.843976 | E26: =IF(D26>0,F26/D26,0) -> 1555.0571 | F26: =F25*(1-$B$5)*(1+$B$6)+IF(A26-Inputs!B17<1,0,OFFSET(C26,-Inputs!B17,0)*(1-$B$5)^Inputs!B17)*$B$3 -> 23083.23 | G26: =F26*$B$4 -> 12118.696 | H26: =$B$9*B26*$B$7 -> 349.95681 | I26: =$B$8 -> 17000 | J26: =G26-H26-I26 -> -5231.2613 | K26: =K25+J26 -> -130766.72 | L26: =MIN(J26:J51) -> -5231.2613
A27: 12 | B27: =IF(Inputs!B22=0,1,1/(1+EXP(-Inputs!B22*(A27-Inputs!B21)))) -> 0.9999546 | C27: =IF(A27-Inputs!B23<1,0,$B$9*IF(Inputs!B22=0,1,1/(1+EXP(-Inputs!B22*(A27-Inputs!B23-Inputs!B21))))) -> 1.9997532 | D27: =D26*(1-$B$5)+IF(A27-Inputs!B17<1,0,OFFSET(C27,-Inputs!B17,0)*(1-$B$5)^Inputs!B17) -> 16.39841 | E27: =IF(D27>0,F27/D27,0) -> 1561.9972 | F27: =F26*(1-$B$5)*(1+$B$6)+IF(A27-Inputs!B17<1,0,OFFSET(C27,-Inputs!B17,0)*(1-$B$5)^Inputs!B17)*$B$3 -> 25614.27 | G27: =F27*$B$4 -> 13447.492 | H27: =$B$9*B27*$B$7 -> 349.98411 | I27: =$B$8 -> 17000 | J27: =G27-H27-I27 -> -3902.4924 | K27: =K26+J27 -> -134669.21 | L27: =MIN(J27:J51) -> -3902.4924
A28: 13 | B28: =IF(Inputs!B22=0,1,1/(1+EXP(-Inputs!B22*(A28-Inputs!B21)))) -> 0.9999833 | C28: =IF(A28-Inputs!B23<1,0,$B$9*IF(Inputs!B22=0,1,1/(1+EXP(-Inputs!B22*(A28-Inputs!B23-Inputs!B21))))) -> 1.9999092 | D28: =D27*(1-$B$5)+IF(A28-Inputs!B17<1,0,OFFSET(C28,-Inputs!B17,0)*(1-$B$5)^Inputs!B17) -> 17.906367 | E28: =IF(D28>0,F28/D28,0) -> 1568.9483 | F28: =F27*(1-$B$5)*(1+$B$6)+IF(A28-Inputs!B17<1,0,OFFSET(C28,-Inputs!B17,0)*(1-$B$5)^Inputs!B17)*$B$3 -> 28094.164 | G28: =F28*$B$4 -> 14749.436 | H28: =$B$9*B28*$B$7 -> 349.99415 | I28: =$B$8 -> 17000 | J28: =G28-H28-I28 -> -2600.558 | K28: =K27+J28 -> -137269.77 | L28: =MIN(J28:J51) -> -2600.558
A29: 14 | B29: =IF(Inputs!B22=0,1,1/(1+EXP(-Inputs!B22*(A29-Inputs!B21)))) -> 0.99999386 | C29: =IF(A29-Inputs!B23<1,0,$B$9*IF(Inputs!B22=0,1,1/(1+EXP(-Inputs!B22*(A29-Inputs!B23-Inputs!B21))))) -> 1.9999666 | D29: =D28*(1-$B$5)+IF(A29-Inputs!B17<1,0,OFFSET(C29,-Inputs!B17,0)*(1-$B$5)^Inputs!B17) -> 19.369142 | E29: =IF(D29>0,F29/D29,0) -> 1575.8985 | F29: =F28*(1-$B$5)*(1+$B$6)+IF(A29-Inputs!B17<1,0,OFFSET(C29,-Inputs!B17,0)*(1-$B$5)^Inputs!B17)*$B$3 -> 30523.802 | G29: =F29*$B$4 -> 16024.996 | H29: =$B$9*B29*$B$7 -> 349.99785 | I29: =$B$8 -> 17000 | J29: =G29-H29-I29 -> -1325.0016 | K29: =K28+J29 -> -138594.77 | L29: =MIN(J29:J51) -> -1325.0016
A30: 15 | B30: =IF(Inputs!B22=0,1,1/(1+EXP(-Inputs!B22*(A30-Inputs!B21)))) -> 0.99999774 | C30: =IF(A30-Inputs!B23<1,0,$B$9*IF(Inputs!B22=0,1,1/(1+EXP(-Inputs!B22*(A30-Inputs!B23-Inputs!B21))))) -> 1.9999877 | D30: =D29*(1-$B$5)+IF(A30-Inputs!B17<1,0,OFFSET(C30,-Inputs!B17,0)*(1-$B$5)^Inputs!B17) -> 20.788056 | E30: =IF(D30>0,F30/D30,0) -> 1582.8392 | F30: =F29*(1-$B$5)*(1+$B$6)+IF(A30-Inputs!B17<1,0,OFFSET(C30,-Inputs!B17,0)*(1-$B$5)^Inputs!B17)*$B$3 -> 32904.151 | G30: =F30*$B$4 -> 17274.679 | H30: =$B$9*B30*$B$7 -> 349.99921 | I30: =$B$8 -> 17000 | J30: =G30-H30-I30 -> -75.320062 | K30: =K29+J30 -> -138670.09 | L30: =MIN(J30:J51) -> -75.320062
A31: 16 | B31: =IF(Inputs!B22=0,1,1/(1+EXP(-Inputs!B22*(A31-Inputs!B21)))) -> 0.99999917 | C31: =IF(A31-Inputs!B23<1,0,$B$9*IF(Inputs!B22=0,1,1/(1+EXP(-Inputs!B22*(A31-Inputs!B23-Inputs!B21))))) -> 1.9999955 | D31: =D30*(1-$B$5)+IF(A31-Inputs!B17<1,0,OFFSET(C31,-Inputs!B17,0)*(1-$B$5)^Inputs!B17) -> 22.16441 | E31: =IF(D31>0,F31/D31,0) -> 1589.7644 | F31: =F30*(1-$B$5)*(1+$B$6)+IF(A31-Inputs!B17<1,0,OFFSET(C31,-Inputs!B17,0)*(1-$B$5)^Inputs!B17)*$B$3 -> 35236.19 | G31: =F31*$B$4 -> 18499 | H31: =$B$9*B31*$B$7 -> 349.99971 | I31: =$B$8 -> 17000 | J31: =G31-H31-I31 -> 1148.9999 | K31: =K30+J31 -> -137521.09 | L31: =MIN(J31:J51) -> 1148.9999
A32: 17 | B32: =IF(Inputs!B22=0,1,1/(1+EXP(-Inputs!B22*(A32-Inputs!B21)))) -> 0.99999969 | C32: =IF(A32-Inputs!B23<1,0,$B$9*IF(Inputs!B22=0,1,1/(1+EXP(-Inputs!B22*(A32-Inputs!B23-Inputs!B21))))) -> 1.9999983 | D32: =D31*(1-$B$5)+IF(A32-Inputs!B17<1,0,OFFSET(C32,-Inputs!B17,0)*(1-$B$5)^Inputs!B17) -> 23.499476 | E32: =IF(D32>0,F32/D32,0) -> 1596.6693 | F32: =F31*(1-$B$5)*(1+$B$6)+IF(A32-Inputs!B17<1,0,OFFSET(C32,-Inputs!B17,0)*(1-$B$5)^Inputs!B17)*$B$3 -> 37520.893 | G32: =F32*$B$4 -> 19698.469 | H32: =$B$9*B32*$B$7 -> 349.99989 | I32: =$B$8 -> 17000 | J32: =G32-H32-I32 -> 2348.4687 | K32: =K31+J32 -> -135172.62 | L32: =MIN(J32:J51) -> 2348.4687
A33: 18 | B33: =IF(Inputs!B22=0,1,1/(1+EXP(-Inputs!B22*(A33-Inputs!B21)))) -> 0.99999989 | C33: =IF(A33-Inputs!B23<1,0,$B$9*IF(Inputs!B22=0,1,1/(1+EXP(-Inputs!B22*(A33-Inputs!B23-Inputs!B21))))) -> 1.9999994 | D33: =D32*(1-$B$5)+IF(A33-Inputs!B17<1,0,OFFSET(C33,-Inputs!B17,0)*(1-$B$5)^Inputs!B17) -> 24.794491 | E33: =IF(D33>0,F33/D33,0) -> 1603.5505 | F33: =F32*(1-$B$5)*(1+$B$6)+IF(A33-Inputs!B17<1,0,OFFSET(C33,-Inputs!B17,0)*(1-$B$5)^Inputs!B17)*$B$3 -> 39759.218 | G33: =F33*$B$4 -> 20873.589 | H33: =$B$9*B33*$B$7 -> 349.99996 | I33: =$B$8 -> 17000 | J33: =G33-H33-I33 -> 3523.5892 | K33: =K32+J33 -> -131649.03 | L33: =MIN(J33:J51) -> 3523.5892
A34: 19 | B34: =IF(Inputs!B22=0,1,1/(1+EXP(-Inputs!B22*(A34-Inputs!B21)))) -> 0.99999996 | C34: =IF(A34-Inputs!B23<1,0,$B$9*IF(Inputs!B22=0,1,1/(1+EXP(-Inputs!B22*(A34-Inputs!B23-Inputs!B21))))) -> 1.9999998 | D34: =D33*(1-$B$5)+IF(A34-Inputs!B17<1,0,OFFSET(C34,-Inputs!B17,0)*(1-$B$5)^Inputs!B17) -> 26.050656 | E34: =IF(D34>0,F34/D34,0) -> 1610.4049 | F34: =F33*(1-$B$5)*(1+$B$6)+IF(A34-Inputs!B17<1,0,OFFSET(C34,-Inputs!B17,0)*(1-$B$5)^Inputs!B17)*$B$3 -> 41952.105 | G34: =F34*$B$4 -> 22024.855 | H34: =$B$9*B34*$B$7 -> 349.99999 | I34: =$B$8 -> 17000 | J34: =G34-H34-I34 -> 4674.8552 | K34: =K33+J34 -> -126974.17 | L34: =MIN(J34:J51) -> 4674.8552
A35: 20 | B35: =IF(Inputs!B22=0,1,1/(1+EXP(-Inputs!B22*(A35-Inputs!B21)))) -> 0.99999998 | C35: =IF(A35-Inputs!B23<1,0,$B$9*IF(Inputs!B22=0,1,1/(1+EXP(-Inputs!B22*(A35-Inputs!B23-Inputs!B21))))) -> 1.9999999 | D35: =D34*(1-$B$5)+IF(A35-Inputs!B17<1,0,OFFSET(C35,-Inputs!B17,0)*(1-$B$5)^Inputs!B17) -> 27.269136 | E35: =IF(D35>0,F35/D35,0) -> 1617.2304 | F35: =F34*(1-$B$5)*(1+$B$6)+IF(A35-Inputs!B17<1,0,OFFSET(C35,-Inputs!B17,0)*(1-$B$5)^Inputs!B17)*$B$3 -> 44100.477 | G35: =F35*$B$4 -> 23152.751 | H35: =$B$9*B35*$B$7 -> 349.99999 | I35: =$B$8 -> 17000 | J35: =G35-H35-I35 -> 5802.7505 | K35: =K34+J35 -> -121171.42 | L35: =MIN(J35:J51) -> 5802.7505
A36: 21 | B36: =IF(Inputs!B22=0,1,1/(1+EXP(-Inputs!B22*(A36-Inputs!B21)))) -> 0.99999999 | C36: =IF(A36-Inputs!B23<1,0,$B$9*IF(Inputs!B22=0,1,1/(1+EXP(-Inputs!B22*(A36-Inputs!B23-Inputs!B21))))) -> 2 | D36: =D35*(1-$B$5)+IF(A36-Inputs!B17<1,0,OFFSET(C36,-Inputs!B17,0)*(1-$B$5)^Inputs!B17) -> 28.451062 | E36: =IF(D36>0,F36/D36,0) -> 1624.0251 | F36: =F35*(1-$B$5)*(1+$B$6)+IF(A36-Inputs!B17<1,0,OFFSET(C36,-Inputs!B17,0)*(1-$B$5)^Inputs!B17)*$B$3 -> 46205.237 | G36: =F36*$B$4 -> 24257.75 | H36: =$B$9*B36*$B$7 -> 350 | I36: =$B$8 -> 17000 | J36: =G36-H36-I36 -> 6907.7497 | K36: =K35+J36 -> -114263.67 | L36: =MIN(J36:J51) -> 6907.7497
A37: 22 | B37: =IF(Inputs!B22=0,1,1/(1+EXP(-Inputs!B22*(A37-Inputs!B21)))) -> 1 | C37: =IF(A37-Inputs!B23<1,0,$B$9*IF(Inputs!B22=0,1,1/(1+EXP(-Inputs!B22*(A37-Inputs!B23-Inputs!B21))))) -> 2 | D37: =D36*(1-$B$5)+IF(A37-Inputs!B17<1,0,OFFSET(C37,-Inputs!B17,0)*(1-$B$5)^Inputs!B17) -> 29.59753 | E37: =IF(D37>0,F37/D37,0) -> 1630.7871 | F37: =F36*(1-$B$5)*(1+$B$6)+IF(A37-Inputs!B17<1,0,OFFSET(C37,-Inputs!B17,0)*(1-$B$5)^Inputs!B17)*$B$3 -> 48267.271 | G37: =F37*$B$4 -> 25340.317 | H37: =$B$9*B37*$B$7 -> 350 | I37: =$B$8 -> 17000 | J37: =G37-H37-I37 -> 7990.3174 | K37: =K36+J37 -> -106273.36 | L37: =MIN(J37:J51) -> 7990.3174
A38: 23 | B38: =IF(Inputs!B22=0,1,1/(1+EXP(-Inputs!B22*(A38-Inputs!B21)))) -> 1 | C38: =IF(A38-Inputs!B23<1,0,$B$9*IF(Inputs!B22=0,1,1/(1+EXP(-Inputs!B22*(A38-Inputs!B23-Inputs!B21))))) -> 2 | D38: =D37*(1-$B$5)+IF(A38-Inputs!B17<1,0,OFFSET(C38,-Inputs!B17,0)*(1-$B$5)^Inputs!B17) -> 30.709604 | E38: =IF(D38>0,F38/D38,0) -> 1637.5153 | F38: =F37*(1-$B$5)*(1+$B$6)+IF(A38-Inputs!B17<1,0,OFFSET(C38,-Inputs!B17,0)*(1-$B$5)^Inputs!B17)*$B$3 -> 50287.446 | G38: =F38*$B$4 -> 26400.909 | H38: =$B$9*B38*$B$7 -> 350 | I38: =$B$8 -> 17000 | J38: =G38-H38-I38 -> 9050.9089 | K38: =K37+J38 -> -97222.448 | L38: =MIN(J38:J51) -> 9050.9089
A39: 24 | B39: =IF(Inputs!B22=0,1,1/(1+EXP(-Inputs!B22*(A39-Inputs!B21)))) -> 1 | C39: =IF(A39-Inputs!B23<1,0,$B$9*IF(Inputs!B22=0,1,1/(1+EXP(-Inputs!B22*(A39-Inputs!B23-Inputs!B21))))) -> 2 | D39: =D38*(1-$B$5)+IF(A39-Inputs!B17<1,0,OFFSET(C39,-Inputs!B17,0)*(1-$B$5)^Inputs!B17) -> 31.788316 | E39: =IF(D39>0,F39/D39,0) -> 1644.2082 | F39: =F38*(1-$B$5)*(1+$B$6)+IF(A39-Inputs!B17<1,0,OFFSET(C39,-Inputs!B17,0)*(1-$B$5)^Inputs!B17)*$B$3 -> 52266.61 | G39: =F39*$B$4 -> 27439.97 | H39: =$B$9*B39*$B$7 -> 350 | I39: =$B$8 -> 17000 | J39: =G39-H39-I39 -> 10089.97 | K39: =K38+J39 -> -87132.478 | L39: =MIN(J39:J51) -> 10089.97
A40: 25 | B40: =IF(Inputs!B22=0,1,1/(1+EXP(-Inputs!B22*(A40-Inputs!B21)))) -> 1 | C40: =IF(A40-Inputs!B23<1,0,$B$9*IF(Inputs!B22=0,1,1/(1+EXP(-Inputs!B22*(A40-Inputs!B23-Inputs!B21))))) -> 2 | D40: =D39*(1-$B$5)+IF(A40-Inputs!B17<1,0,OFFSET(C40,-Inputs!B17,0)*(1-$B$5)^Inputs!B17) -> 32.834667 | E40: =IF(D40>0,F40/D40,0) -> 1650.8649 | F40: =F39*(1-$B$5)*(1+$B$6)+IF(A40-Inputs!B17<1,0,OFFSET(C40,-Inputs!B17,0)*(1-$B$5)^Inputs!B17)*$B$3 -> 54205.598 | G40: =F40*$B$4 -> 28457.939 | H40: =$B$9*B40*$B$7 -> 350 | I40: =$B$8 -> 17000 | J40: =G40-H40-I40 -> 11107.939 | K40: =K39+J40 -> -76024.539 | L40: =MIN(J40:J51) -> 11107.939
A41: 26 | B41: =IF(Inputs!B22=0,1,1/(1+EXP(-Inputs!B22*(A41-Inputs!B21)))) -> 1 | C41: =IF(A41-Inputs!B23<1,0,$B$9*IF(Inputs!B22=0,1,1/(1+EXP(-Inputs!B22*(A41-Inputs!B23-Inputs!B21))))) -> 2 | D41: =D40*(1-$B$5)+IF(A41-Inputs!B17<1,0,OFFSET(C41,-Inputs!B17,0)*(1-$B$5)^Inputs!B17) -> 33.849627 | E41: =IF(D41>0,F41/D41,0) -> 1657.4843 | F41: =F40*(1-$B$5)*(1+$B$6)+IF(A41-Inputs!B17<1,0,OFFSET(C41,-Inputs!B17,0)*(1-$B$5)^Inputs!B17)*$B$3 -> 56105.225 | G41: =F41*$B$4 -> 29455.243 | H41: =$B$9*B41*$B$7 -> 350 | I41: =$B$8 -> 17000 | J41: =G41-H41-I41 -> 12105.243 | K41: =K40+J41 -> -63919.296 | L41: =MIN(J41:J51) -> 12105.243
A42: 27 | B42: =IF(Inputs!B22=0,1,1/(1+EXP(-Inputs!B22*(A42-Inputs!B21)))) -> 1 | C42: =IF(A42-Inputs!B23<1,0,$B$9*IF(Inputs!B22=0,1,1/(1+EXP(-Inputs!B22*(A42-Inputs!B23-Inputs!B21))))) -> 2 | D42: =D41*(1-$B$5)+IF(A42-Inputs!B17<1,0,OFFSET(C42,-Inputs!B17,0)*(1-$B$5)^Inputs!B17) -> 34.834138 | E42: =IF(D42>0,F42/D42,0) -> 1664.0655 | F42: =F41*(1-$B$5)*(1+$B$6)+IF(A42-Inputs!B17<1,0,OFFSET(C42,-Inputs!B17,0)*(1-$B$5)^Inputs!B17)*$B$3 -> 57966.288 | G42: =F42*$B$4 -> 30432.301 | H42: =$B$9*B42*$B$7 -> 350 | I42: =$B$8 -> 17000 | J42: =G42-H42-I42 -> 13082.301 | K42: =K41+J42 -> -50836.994 | L42: =MIN(J42:J51) -> 13082.301
A43: 28 | B43: =IF(Inputs!B22=0,1,1/(1+EXP(-Inputs!B22*(A43-Inputs!B21)))) -> 1 | C43: =IF(A43-Inputs!B23<1,0,$B$9*IF(Inputs!B22=0,1,1/(1+EXP(-Inputs!B22*(A43-Inputs!B23-Inputs!B21))))) -> 2 | D43: =D42*(1-$B$5)+IF(A43-Inputs!B17<1,0,OFFSET(C43,-Inputs!B17,0)*(1-$B$5)^Inputs!B17) -> 35.789114 | E43: =IF(D43>0,F43/D43,0) -> 1670.6078 | F43: =F42*(1-$B$5)*(1+$B$6)+IF(A43-Inputs!B17<1,0,OFFSET(C43,-Inputs!B17,0)*(1-$B$5)^Inputs!B17)*$B$3 -> 59789.573 | G43: =F43*$B$4 -> 31389.526 | H43: =$B$9*B43*$B$7 -> 350 | I43: =$B$8 -> 17000 | J43: =G43-H43-I43 -> 14039.526 | K43: =K42+J43 -> -36797.469 | L43: =MIN(J43:J51) -> 14039.526
...

Sheet Market
A1: Market case
A3: Revenue per customer-month (ARPU₀) | B3: =Inputs!C5 -> 2775
A4: Gross margin | B4: =Inputs!C6 -> 0.525
A5: Monthly churn | B5: =Inputs!C7 -> 0.03
A6: Monthly expansion | B6: =Inputs!C8 -> 0.01
A7: Blended CAC | B7: =Inputs!C11 -> 175
A8: Fixed burn / month | B8: =Inputs!B14*Inputs!C10+Inputs!B15 -> 17000
A9: New customers / month at full capacity | B9: =Inputs!C9 -> 2
A10: LTV (lifetime contribution, 60-mo cap) | B10: =B3*B4*(1-B5)^Inputs!B17*IF(ABS(1-(1-B5)*(1+B6))<0.000001,MAX(0,60-Inputs!B17),(1-((1-B5)*(1+B6))^MAX(0,60-Inputs!B17))/(1-(1-B5)*(1+B6))) -> 50801.379
A11: LTV / CAC (cash) | B11: =IF(B7>0,B10/B7,"n/a") -> 290.29359
A12: Payback (months, cumulative; "none" = not within 60) | B12: =IF(B3*B4<=0,"none",IF(B7<=0,1+Inputs!B17,IF((1-B5)*(1+B6)<=0,IF(B7<=B3*B4*(1-B5)^Inputs!B17,1+Inputs!B17,"none"),IF(ABS(1-(1-B5)*(1+B6))<0.000001,IF(B7/(B3*B4*(1-B5)^Inputs!B17)<=60-Inputs!B17,ROUNDUP(B7/(B3*B4*(1-B5)^Inputs!B17),0)+Inputs!B17,"none"),IF(1-B7*(1-(1-B5)*(1+B6))/(B3*B4*(1-B5)^Inputs!B17)<=0,"none",IF(ROUNDUP(LN(1-B7*(1-(1-B5)*(1+B6))/(B3*B4*(1-B5)^Inputs!B17))/LN((1-B5)*(1+B6)),0)<=60-Inputs!B17,ROUNDUP(LN(1-B7*(1-(1-B5)*(1+B6))/(B3*B4*(1-B5)^Inputs!B17))/LN((1-B5)*(1+B6)),0)+Inputs!B17,"none")))))) -> 1
A15: Month | B15: Ramp | C15: New customers (arrivals) | D15: Paying customers | E15: ARPU (derived) | F15: Revenue | G15: Gross profit | H15: Acquisition spend | I15: Fixed burn | J15: Net cash flow | K15: Cumulative cash | L15: Lowest net from here on
A16: 1 | B16: =IF(Inputs!B22=0,1,1/(1+EXP(-Inputs!B22*(A16-Inputs!B21)))) -> 0.26894142 | C16: =IF(A16-Inputs!B23<1,0,$B$9*IF(Inputs!B22=0,1,1/(1+EXP(-Inputs!B22*(A16-Inputs!B23-Inputs!B21))))) -> 0 | D16: =Inputs!B19*(1-$B$5)+IF(A16-Inputs!B17<1,0,OFFSET(C16,-Inputs!B17,0)*(1-$B$5)^Inputs!B17) -> 0 | E16: =IF(D16>0,F16/D16,0) -> 0 | F16: =Inputs!B20*(1-$B$5)*(1+$B$6)+IF(A16-Inputs!B17<1,0,OFFSET(C16,-Inputs!B17,0)*(1-$B$5)^Inputs!B17)*$B$3 -> 0 | G16: =F16*$B$4 -> 0 | H16: =$B$9*B16*$B$7 -> 94.129497 | I16: =$B$8 -> 17000 | J16: =G16-H16-I16 -> -17094.129 | K16: =J16-Inputs!B16 -> -17094.129 | L16: =MIN(J16:J51) -> -17094.129
A17: 2 | B17: =IF(Inputs!B22=0,1,1/(1+EXP(-Inputs!B22*(A17-Inputs!B21)))) -> 0.5 | C17: =IF(A17-Inputs!B23<1,0,$B$9*IF(Inputs!B22=0,1,1/(1+EXP(-Inputs!B22*(A17-Inputs!B23-Inputs!B21))))) -> 0.53788284 | D17: =D16*(1-$B$5)+IF(A17-Inputs!B17<1,0,OFFSET(C17,-Inputs!B17,0)*(1-$B$5)^Inputs!B17) -> 0.53788284 | E17: =IF(D17>0,F17/D17,0) -> 2775 | F17: =F16*(1-$B$5)*(1+$B$6)+IF(A17-Inputs!B17<1,0,OFFSET(C17,-Inputs!B17,0)*(1-$B$5)^Inputs!B17)*$B$3 -> 1492.6249 | G17: =F17*$B$4 -> 783.62807 | H17: =$B$9*B17*$B$7 -> 175 | I17: =$B$8 -> 17000 | J17: =G17-H17-I17 -> -16391.372 | K17: =K16+J17 -> -33485.501 | L17: =MIN(J17:J51) -> -16391.372
A18: 3 | B18: =IF(Inputs!B22=0,1,1/(1+EXP(-Inputs!B22*(A18-Inputs!B21)))) -> 0.73105858 | C18: =IF(A18-Inputs!B23<1,0,$B$9*IF(Inputs!B22=0,1,1/(1+EXP(-Inputs!B22*(A18-Inputs!B23-Inputs!B21))))) -> 1 | D18: =D17*(1-$B$5)+IF(A18-Inputs!B17<1,0,OFFSET(C18,-Inputs!B17,0)*(1-$B$5)^Inputs!B17) -> 1.5217464 | E18: =IF(D18>0,F18/D18,0) -> 2784.5144 | F18: =F17*(1-$B$5)*(1+$B$6)+IF(A18-Inputs!B17<1,0,OFFSET(C18,-Inputs!B17,0)*(1-$B$5)^Inputs!B17)*$B$3 -> 4237.3246 | G18: =F18*$B$4 -> 2224.5954 | H18: =$B$9*B18*$B$7 -> 255.8705 | I18: =$B$8 -> 17000 | J18: =G18-H18-I18 -> -15031.275 | K18: =K17+J18 -> -48516.777 | L18: =MIN(J18:J51) -> -15031.275
A19: 4 | B19: =IF(Inputs!B22=0,1,1/(1+EXP(-Inputs!B22*(A19-Inputs!B21)))) -> 0.88079708 | C19: =IF(A19-Inputs!B23<1,0,$B$9*IF(Inputs!B22=0,1,1/(1+EXP(-Inputs!B22*(A19-Inputs!B23-Inputs!B21))))) -> 1.4621172 | D19: =D18*(1-$B$5)+IF(A19-Inputs!B17<1,0,OFFSET(C19,-Inputs!B17,0)*(1-$B$5)^Inputs!B17) -> 2.9382111 | E19: =IF(D19>0,F19/D19,0) -> 2793.7686 | F19: =F18*(1-$B$5)*(1+$B$6)+IF(A19-Inputs!B17<1,0,OFFSET(C19,-Inputs!B17,0)*(1-$B$5)^Inputs!B17)*$B$3 -> 8208.682 | G19: =F19*$B$4 -> 4309.5581 | H19: =$B$9*B19*$B$7 -> 308.27898 | I19: =$B$8 -> 17000 | J19: =G19-H19-I19 -> -12998.721 | K19: =K18+J19 -> -61515.497 | L19: =MIN(J19:J51) -> -12998.721
A20: 5 | B20: =IF(Inputs!B22=0,1,1/(1+EXP(-Inputs!B22*(A20-Inputs!B21)))) -> 0.95257413 | C20: =IF(A20-Inputs!B23<1,0,$B$9*IF(Inputs!B22=0,1,1/(1+EXP(-Inputs!B22*(A20-Inputs!B23-Inputs!B21))))) -> 1.7615942 | D20: =D19*(1-$B$5)+IF(A20-Inputs!B17<1,0,OFFSET(C20,-Inputs!B17,0)*(1-$B$5)^Inputs!B17) -> 4.6116589 | E20: =IF(D20>0,F20/D20,0) -> 2803.8651 | F20: =F19*(1-$B$5)*(1+$B$6)+IF(A20-Inputs!B17<1,0,OFFSET(C20,-Inputs!B17,0)*(1-$B$5)^Inputs!B17)*$B$3 -> 12930.47 | G20: =F20*$B$4 -> 6788.4965 | H20: =$B$9*B20*$B$7 -> 333.40094 | I20: =$B$8 -> 17000 | J20: =G20-H20-I20 -> -10544.904 | K20: =K19+J20 -> -72060.402 | L20: =MIN(J20:J51) -> -10544.904
A21: 6 | B21: =IF(Inputs!B22=0,1,1/(1+EXP(-Inputs!B22*(A21-Inputs!B21)))) -> 0.98201379 | C21: =IF(A21-Inputs!B23<1,0,$B$9*IF(Inputs!B22=0,1,1/(1+EXP(-Inputs!B22*(A21-Inputs!B23-Inputs!B21))))) -> 1.9051483 | D21: =D20*(1-$B$5)+IF(A21-Inputs!B17<1,0,OFFSET(C21,-Inputs!B17,0)*(1-$B$5)^Inputs!B17) -> 6.3784574 | E21: =IF(D21>0,F21/D21,0) -> 2814.9075 | F21: =F20*(1-$B$5)*(1+$B$6)+IF(A21-Inputs!B17<1,0,OFFSET(C21,-Inputs!B17,0)*(1-$B$5)^Inputs!B17)*$B$3 -> 17954.767 | G21: =F21*$B$4 -> 9426.2529 | H21: =$B$9*B21*$B$7 -> 343.70483 | I21: =$B$8 -> 17000 | J21: =G21-H21-I21 -> -7917.4519 | K21: =K20+J21 -> -79977.854 | L21: =MIN(J21:J51) -> -7917.4519
A22: 7 | B22: =IF(Inputs!B22=0,1,1/(1+EXP(-Inputs!B22*(A22-Inputs!B21)))) -> 0.99330715 | C22: =IF(A22-Inputs!B23<1,0,$B$9*IF(Inputs!B22=0,1,1/(1+EXP(-Inputs!B22*(A22-Inputs!B23-Inputs!B21))))) -> 1.9640276 | D22: =D21*(1-$B$5)+IF(A22-Inputs!B17<1,0,OFFSET(C22,-Inputs!B17,0)*(1-$B$5)^Inputs!B17) -> 8.1511313 | E22: =IF(D22>0,F22/D22,0) -> 2826.6582 | F22: =F21*(1-$B$5)*(1+$B$6)+IF(A22-Inputs!B17<1,0,OFFSET(C22,-Inputs!B17,0)*(1-$B$5)^Inputs!B17)*$B$3 -> 23040.462 | G22: =F22*$B$4 -> 12096.243 | H22: =$B$9*B22*$B$7 -> 347.6575 | I22: =$B$8 -> 17000 | J22: =G22-H22-I22 -> -5251.4149 | K22: =K21+J22 -> -85229.269 | L22: =MIN(J22:J51) -> -5251.4149
A23: 8 | B23: =IF(Inputs!B22=0,1,1/(1+EXP(-Inputs!B22*(A23-Inputs!B21)))) -> 0.99752738 | C23: =IF(A23-Inputs!B23<1,0,$B$9*IF(Inputs!B22=0,1,1/(1+EXP(-Inputs!B22*(A23-Inputs!B23-Inputs!B21))))) -> 1.9866143 | D23: =D22*(1-$B$5)+IF(A23-Inputs!B17<1,0,OFFSET(C23,-Inputs!B17,0)*(1-$B$5)^Inputs!B17) -> 9.8932116 | E23: =IF(D23>0,F23/D23,0) -> 2838.8754 | F23: =F22*(1-$B$5)*(1+$B$6)+IF(A23-Inputs!B17<1,0,OFFSET(C23,-Inputs!B17,0)*(1-$B$5)^Inputs!B17)*$B$3 -> 28085.595 | G23: =F23*$B$4 -> 14744.938 | H23: =$B$9*B23*$B$7 -> 349.13458 | I23: =$B$8 -> 17000 | J23: =G23-H23-I23 -> -2604.197 | K23: =K22+J23 -> -87833.466 | L23: =MIN(J23:J51) -> -2604.197
A24: 9 | B24: =IF(Inputs!B22=0,1,1/(1+EXP(-Inputs!B22*(A24-Inputs!B21)))) -> 0.99908895 | C24: =IF(A24-Inputs!B23<1,0,$B$9*IF(Inputs!B22=0,1,1/(1+EXP(-Inputs!B22*(A24-Inputs!B23-Inputs!B21))))) -> 1.9950548 | D24: =D23*(1-$B$5)+IF(A24-Inputs!B17<1,0,OFFSET(C24,-Inputs!B17,0)*(1-$B$5)^Inputs!B17) -> 11.59147 | E24: =IF(D24>0,F24/D24,0) -> 2851.3842 | F24: =F23*(1-$B$5)*(1+$B$6)+IF(A24-Inputs!B17<1,0,OFFSET(C24,-Inputs!B17,0)*(1-$B$5)^Inputs!B17)*$B$3 -> 33051.735 | G24: =F24*$B$4 -> 17352.161 | H24: =$B$9*B24*$B$7 -> 349.68113 | I24: =$B$8 -> 17000 | J24: =G24-H24-I24 -> 2.4796581 | K24: =K23+J24 -> -87830.986 | L24: =MIN(J24:J51) -> 2.4796581
A25: 10 | B25: =IF(Inputs!B22=0,1,1/(1+EXP(-Inputs!B22*(A25-Inputs!B21)))) -> 0.99966465 | C25: =IF(A25-Inputs!B23<1,0,$B$9*IF(Inputs!B22=0,1,1/(1+EXP(-Inputs!B22*(A25-Inputs!B23-Inputs!B21))))) -> 1.9981779 | D25: =D24*(1-$B$5)+IF(A25-Inputs!B17<1,0,OFFSET(C25,-Inputs!B17,0)*(1-$B$5)^Inputs!B17) -> 13.241904 | E25: =IF(D25>0,F25/D25,0) -> 2864.0691 | F25: =F24*(1-$B$5)*(1+$B$6)+IF(A25-Inputs!B17<1,0,OFFSET(C25,-Inputs!B17,0)*(1-$B$5)^Inputs!B17)*$B$3 -> 37925.728 | G25: =F25*$B$4 -> 19911.007 | H25: =$B$9*B25*$B$7 -> 349.88263 | I25: =$B$8 -> 17000 | J25: =G25-H25-I25 -> 2561.1247 | K25: =K24+J25 -> -85269.861 | L25: =MIN(J25:J51) -> 2561.1247
A26: 11 | B26: =IF(Inputs!B22=0,1,1/(1+EXP(-Inputs!B22*(A26-Inputs!B21)))) -> 0.99987661 | C26: =IF(A26-Inputs!B23<1,0,$B$9*IF(Inputs!B22=0,1,1/(1+EXP(-Inputs!B22*(A26-Inputs!B23-Inputs!B21))))) -> 1.9993293 | D26: =D25*(1-$B$5)+IF(A26-Inputs!B17<1,0,OFFSET(C26,-Inputs!B17,0)*(1-$B$5)^Inputs!B17) -> 14.843976 | E26: =IF(D26>0,F26/D26,0) -> 2876.8555 | F26: =F25*(1-$B$5)*(1+$B$6)+IF(A26-Inputs!B17<1,0,OFFSET(C26,-Inputs!B17,0)*(1-$B$5)^Inputs!B17)*$B$3 -> 42703.975 | G26: =F26*$B$4 -> 22419.587 | H26: =$B$9*B26*$B$7 -> 349.95681 | I26: =$B$8 -> 17000 | J26: =G26-H26-I26 -> 5069.63 | K26: =K25+J26 -> -80200.231 | L26: =MIN(J26:J51) -> 5069.63
A27: 12 | B27: =IF(Inputs!B22=0,1,1/(1+EXP(-Inputs!B22*(A27-Inputs!B21)))) -> 0.9999546 | C27: =IF(A27-Inputs!B23<1,0,$B$9*IF(Inputs!B22=0,1,1/(1+EXP(-Inputs!B22*(A27-Inputs!B23-Inputs!B21))))) -> 1.9997532 | D27: =D26*(1-$B$5)+IF(A27-Inputs!B17<1,0,OFFSET(C27,-Inputs!B17,0)*(1-$B$5)^Inputs!B17) -> 16.39841 | E27: =IF(D27>0,F27/D27,0) -> 2889.6948 | F27: =F26*(1-$B$5)*(1+$B$6)+IF(A27-Inputs!B17<1,0,OFFSET(C27,-Inputs!B17,0)*(1-$B$5)^Inputs!B17)*$B$3 -> 47386.399 | G27: =F27*$B$4 -> 24877.86 | H27: =$B$9*B27*$B$7 -> 349.98411 | I27: =$B$8 -> 17000 | J27: =G27-H27-I27 -> 7527.8755 | K27: =K26+J27 -> -72672.356 | L27: =MIN(J27:J51) -> 7527.8755
A28: 13 | B28: =IF(Inputs!B22=0,1,1/(1+EXP(-Inputs!B22*(A28-Inputs!B21)))) -> 0.9999833 | C28: =IF(A28-Inputs!B23<1,0,$B$9*IF(Inputs!B22=0,1,1/(1+EXP(-Inputs!B22*(A28-Inputs!B23-Inputs!B21))))) -> 1.9999092 | D28: =D27*(1-$B$5)+IF(A28-Inputs!B17<1,0,OFFSET(C28,-Inputs!B17,0)*(1-$B$5)^Inputs!B17) -> 17.906367 | E28: =IF(D28>0,F28/D28,0) -> 2902.5544 | F28: =F27*(1-$B$5)*(1+$B$6)+IF(A28-Inputs!B17<1,0,OFFSET(C28,-Inputs!B17,0)*(1-$B$5)^Inputs!B17)*$B$3 -> 51974.203 | G28: =F28*$B$4 -> 27286.457 | H28: =$B$9*B28*$B$7 -> 349.99415 | I28: =$B$8 -> 17000 | J28: =G28-H28-I28 -> 9936.4626 | K28: =K27+J28 -> -62735.893 | L28: =MIN(J28:J51) -> 9936.4626
A29: 14 | B29: =IF(Inputs!B22=0,1,1/(1+EXP(-Inputs!B22*(A29-Inputs!B21)))) -> 0.99999386 | C29: =IF(A29-Inputs!B23<1,0,$B$9*IF(Inputs!B22=0,1,1/(1+EXP(-Inputs!B22*(A29-Inputs!B23-Inputs!B21))))) -> 1.9999666 | D29: =D28*(1-$B$5)+IF(A29-Inputs!B17<1,0,OFFSET(C29,-Inputs!B17,0)*(1-$B$5)^Inputs!B17) -> 19.369142 | E29: =IF(D29>0,F29/D29,0) -> 2915.4122 | F29: =F28*(1-$B$5)*(1+$B$6)+IF(A29-Inputs!B17<1,0,OFFSET(C29,-Inputs!B17,0)*(1-$B$5)^Inputs!B17)*$B$3 -> 56469.034 | G29: =F29*$B$4 -> 29646.243 | H29: =$B$9*B29*$B$7 -> 349.99785 | I29: =$B$8 -> 17000 | J29: =G29-H29-I29 -> 12296.245 | K29: =K28+J29 -> -50439.648 | L29: =MIN(J29:J51) -> 12296.245
A30: 15 | B30: =IF(Inputs!B22=0,1,1/(1+EXP(-Inputs!B22*(A30-Inputs!B21)))) -> 0.99999774 | C30: =IF(A30-Inputs!B23<1,0,$B$9*IF(Inputs!B22=0,1,1/(1+EXP(-Inputs!B22*(A30-Inputs!B23-Inputs!B21))))) -> 1.9999877 | D30: =D29*(1-$B$5)+IF(A30-Inputs!B17<1,0,OFFSET(C30,-Inputs!B17,0)*(1-$B$5)^Inputs!B17) -> 20.788056 | E30: =IF(D30>0,F30/D30,0) -> 2928.2526 | F30: =F29*(1-$B$5)*(1+$B$6)+IF(A30-Inputs!B17<1,0,OFFSET(C30,-Inputs!B17,0)*(1-$B$5)^Inputs!B17)*$B$3 -> 60872.679 | G30: =F30*$B$4 -> 31958.156 | H30: =$B$9*B30*$B$7 -> 349.99921 | I30: =$B$8 -> 17000 | J30: =G30-H30-I30 -> 14608.157 | K30: =K29+J30 -> -35831.491 | L30: =MIN(J30:J51) -> 14608.157
A31: 16 | B31: =IF(Inputs!B22=0,1,1/(1+EXP(-Inputs!B22*(A31-Inputs!B21)))) -> 0.99999917 | C31: =IF(A31-Inputs!B23<1,0,$B$9*IF(Inputs!B22=0,1,1/(1+EXP(-Inputs!B22*(A31-Inputs!B23-Inputs!B21))))) -> 1.9999955 | D31: =D30*(1-$B$5)+IF(A31-Inputs!B17<1,0,OFFSET(C31,-Inputs!B17,0)*(1-$B$5)^Inputs!B17) -> 22.16441 | E31: =IF(D31>0,F31/D31,0) -> 2941.0642 | F31: =F30*(1-$B$5)*(1+$B$6)+IF(A31-Inputs!B17<1,0,OFFSET(C31,-Inputs!B17,0)*(1-$B$5)^Inputs!B17)*$B$3 -> 65186.951 | G31: =F31*$B$4 -> 34223.149 | H31: =$B$9*B31*$B$7 -> 349.99971 | I31: =$B$8 -> 17000 | J31: =G31-H31-I31 -> 16873.15 | K31: =K30+J31 -> -18958.341 | L31: =MIN(J31:J51) -> 16873.15
A32: 17 | B32: =IF(Inputs!B22=0,1,1/(1+EXP(-Inputs!B22*(A32-Inputs!B21)))) -> 0.99999969 | C32: =IF(A32-Inputs!B23<1,0,$B$9*IF(Inputs!B22=0,1,1/(1+EXP(-Inputs!B22*(A32-Inputs!B23-Inputs!B21))))) -> 1.9999983 | D32: =D31*(1-$B$5)+IF(A32-Inputs!B17<1,0,OFFSET(C32,-Inputs!B17,0)*(1-$B$5)^Inputs!B17) -> 23.499476 | E32: =IF(D32>0,F32/D32,0) -> 2953.8383 | F32: =F31*(1-$B$5)*(1+$B$6)+IF(A32-Inputs!B17<1,0,OFFSET(C32,-Inputs!B17,0)*(1-$B$5)^Inputs!B17)*$B$3 -> 69413.651 | G32: =F32*$B$4 -> 36442.167 | H32: =$B$9*B32*$B$7 -> 349.99989 | I32: =$B$8 -> 17000 | J32: =G32-H32-I32 -> 19092.167 | K32: =K31+J32 -> 133.8259 | L32: =MIN(J32:J51) -> 19092.167
A33: 18 | B33: =IF(Inputs!B22=0,1,1/(1+EXP(-Inputs!B22*(A33-Inputs!B21)))) -> 0.99999989 | C33: =IF(A33-Inputs!B23<1,0,$B$9*IF(Inputs!B22=0,1,1/(1+EXP(-Inputs!B22*(A33-Inputs!B23-Inputs!B21))))) -> 1.9999994 | D33: =D32*(1-$B$5)+IF(A33-Inputs!B17<1,0,OFFSET(C33,-Inputs!B17,0)*(1-$B$5)^Inputs!B17) -> 24.794491 | E33: =IF(D33>0,F33/D33,0) -> 2966.5684 | F33: =F32*(1-$B$5)*(1+$B$6)+IF(A33-Inputs!B17<1,0,OFFSET(C33,-Inputs!B17,0)*(1-$B$5)^Inputs!B17)*$B$3 -> 73554.552 | G33: =F33*$B$4 -> 38616.14 | H33: =$B$9*B33*$B$7 -> 349.99996 | I33: =$B$8 -> 17000 | J33: =G33-H33-I33 -> 21266.14 | K33: =K32+J33 -> 21399.966 | L33: =MIN(J33:J51) -> 21266.14
A34: 19 | B34: =IF(Inputs!B22=0,1,1/(1+EXP(-Inputs!B22*(A34-Inputs!B21)))) -> 0.99999996 | C34: =IF(A34-Inputs!B23<1,0,$B$9*IF(Inputs!B22=0,1,1/(1+EXP(-Inputs!B22*(A34-Inputs!B23-Inputs!B21))))) -> 1.9999998 | D34: =D33*(1-$B$5)+IF(A34-Inputs!B17<1,0,OFFSET(C34,-Inputs!B17,0)*(1-$B$5)^Inputs!B17) -> 26.050656 | E34: =IF(D34>0,F34/D34,0) -> 2979.2491 | F34: =F33*(1-$B$5)*(1+$B$6)+IF(A34-Inputs!B17<1,0,OFFSET(C34,-Inputs!B17,0)*(1-$B$5)^Inputs!B17)*$B$3 -> 77611.394 | G34: =F34*$B$4 -> 40745.982 | H34: =$B$9*B34*$B$7 -> 349.99999 | I34: =$B$8 -> 17000 | J34: =G34-H34-I34 -> 23395.982 | K34: =K33+J34 -> 44795.948 | L34: =MIN(J34:J51) -> 23395.982
A35: 20 | B35: =IF(Inputs!B22=0,1,1/(1+EXP(-Inputs!B22*(A35-Inputs!B21)))) -> 0.99999998 | C35: =IF(A35-Inputs!B23<1,0,$B$9*IF(Inputs!B22=0,1,1/(1+EXP(-Inputs!B22*(A35-Inputs!B23-Inputs!B21))))) -> 1.9999999 | D35: =D34*(1-$B$5)+IF(A35-Inputs!B17<1,0,OFFSET(C35,-Inputs!B17,0)*(1-$B$5)^Inputs!B17) -> 27.269136 | E35: =IF(D35>0,F35/D35,0) -> 2991.8763 | F35: =F34*(1-$B$5)*(1+$B$6)+IF(A35-Inputs!B17<1,0,OFFSET(C35,-Inputs!B17,0)*(1-$B$5)^Inputs!B17)*$B$3 -> 81585.883 | G35: =F35*$B$4 -> 42832.589 | H35: =$B$9*B35*$B$7 -> 349.99999 | I35: =$B$8 -> 17000 | J35: =G35-H35-I35 -> 25482.589 | K35: =K34+J35 -> 70278.537 | L35: =MIN(J35:J51) -> 25482.589
A36: 21 | B36: =IF(Inputs!B22=0,1,1/(1+EXP(-Inputs!B22*(A36-Inputs!B21)))) -> 0.99999999 | C36: =IF(A36-Inputs!B23<1,0,$B$9*IF(Inputs!B22=0,1,1/(1+EXP(-Inputs!B22*(A36-Inputs!B23-Inputs!B21))))) -> 2 | D36: =D35*(1-$B$5)+IF(A36-Inputs!B17<1,0,OFFSET(C36,-Inputs!B17,0)*(1-$B$5)^Inputs!B17) -> 28.451062 | E36: =IF(D36>0,F36/D36,0) -> 3004.4463 | F36: =F35*(1-$B$5)*(1+$B$6)+IF(A36-Inputs!B17<1,0,OFFSET(C36,-Inputs!B17,0)*(1-$B$5)^Inputs!B17)*$B$3 -> 85479.689 | G36: =F36*$B$4 -> 44876.837 | H36: =$B$9*B36*$B$7 -> 350 | I36: =$B$8 -> 17000 | J36: =G36-H36-I36 -> 27526.837 | K36: =K35+J36 -> 97805.373 | L36: =MIN(J36:J51) -> 27526.837
A37: 22 | B37: =IF(Inputs!B22=0,1,1/(1+EXP(-Inputs!B22*(A37-Inputs!B21)))) -> 1 | C37: =IF(A37-Inputs!B23<1,0,$B$9*IF(Inputs!B22=0,1,1/(1+EXP(-Inputs!B22*(A37-Inputs!B23-Inputs!B21))))) -> 2 | D37: =D36*(1-$B$5)+IF(A37-Inputs!B17<1,0,OFFSET(C37,-Inputs!B17,0)*(1-$B$5)^Inputs!B17) -> 29.59753 | E37: =IF(D37>0,F37/D37,0) -> 3016.9562 | F37: =F36*(1-$B$5)*(1+$B$6)+IF(A37-Inputs!B17<1,0,OFFSET(C37,-Inputs!B17,0)*(1-$B$5)^Inputs!B17)*$B$3 -> 89294.452 | G37: =F37*$B$4 -> 46879.587 | H37: =$B$9*B37*$B$7 -> 350 | I37: =$B$8 -> 17000 | J37: =G37-H37-I37 -> 29529.587 | K37: =K36+J37 -> 127334.96 | L37: =MIN(J37:J51) -> 29529.587
A38: 23 | B38: =IF(Inputs!B22=0,1,1/(1+EXP(-Inputs!B22*(A38-Inputs!B21)))) -> 1 | C38: =IF(A38-Inputs!B23<1,0,$B$9*IF(Inputs!B22=0,1,1/(1+EXP(-Inputs!B22*(A38-Inputs!B23-Inputs!B21))))) -> 2 | D38: =D37*(1-$B$5)+IF(A38-Inputs!B17<1,0,OFFSET(C38,-Inputs!B17,0)*(1-$B$5)^Inputs!B17) -> 30.709604 | E38: =IF(D38>0,F38/D38,0) -> 3029.4032 | F38: =F37*(1-$B$5)*(1+$B$6)+IF(A38-Inputs!B17<1,0,OFFSET(C38,-Inputs!B17,0)*(1-$B$5)^Inputs!B17)*$B$3 -> 93031.774 | G38: =F38*$B$4 -> 48841.681 | H38: =$B$9*B38*$B$7 -> 350 | I38: =$B$8 -> 17000 | J38: =G38-H38-I38 -> 31491.681 | K38: =K37+J38 -> 158826.64 | L38: =MIN(J38:J51) -> 31491.681
A39: 24 | B39: =IF(Inputs!B22=0,1,1/(1+EXP(-Inputs!B22*(A39-Inputs!B21)))) -> 1 | C39: =IF(A39-Inputs!B23<1,0,$B$9*IF(Inputs!B22=0,1,1/(1+EXP(-Inputs!B22*(A39-Inputs!B23-Inputs!B21))))) -> 2 | D39: =D38*(1-$B$5)+IF(A39-Inputs!B17<1,0,OFFSET(C39,-Inputs!B17,0)*(1-$B$5)^Inputs!B17) -> 31.788316 | E39: =IF(D39>0,F39/D39,0) -> 3041.7852 | F39: =F38*(1-$B$5)*(1+$B$6)+IF(A39-Inputs!B17<1,0,OFFSET(C39,-Inputs!B17,0)*(1-$B$5)^Inputs!B17)*$B$3 -> 96693.229 | G39: =F39*$B$4 -> 50763.945 | H39: =$B$9*B39*$B$7 -> 350 | I39: =$B$8 -> 17000 | J39: =G39-H39-I39 -> 33413.945 | K39: =K38+J39 -> 192240.59 | L39: =MIN(J39:J51) -> 33413.945
A40: 25 | B40: =IF(Inputs!B22=0,1,1/(1+EXP(-Inputs!B22*(A40-Inputs!B21)))) -> 1 | C40: =IF(A40-Inputs!B23<1,0,$B$9*IF(Inputs!B22=0,1,1/(1+EXP(-Inputs!B22*(A40-Inputs!B23-Inputs!B21))))) -> 2 | D40: =D39*(1-$B$5)+IF(A40-Inputs!B17<1,0,OFFSET(C40,-Inputs!B17,0)*(1-$B$5)^Inputs!B17) -> 32.834667 | E40: =IF(D40>0,F40/D40,0) -> 3054.1 | F40: =F39*(1-$B$5)*(1+$B$6)+IF(A40-Inputs!B17<1,0,OFFSET(C40,-Inputs!B17,0)*(1-$B$5)^Inputs!B17)*$B$3 -> 100280.36 | G40: =F40*$B$4 -> 52647.187 | H40: =$B$9*B40*$B$7 -> 350 | I40: =$B$8 -> 17000 | J40: =G40-H40-I40 -> 35297.187 | K40: =K39+J40 -> 227537.77 | L40: =MIN(J40:J51) -> 35297.187
A41: 26 | B41: =IF(Inputs!B22=0,1,1/(1+EXP(-Inputs!B22*(A41-Inputs!B21)))) -> 1 | C41: =IF(A41-Inputs!B23<1,0,$B$9*IF(Inputs!B22=0,1,1/(1+EXP(-Inputs!B22*(A41-Inputs!B23-Inputs!B21))))) -> 2 | D41: =D40*(1-$B$5)+IF(A41-Inputs!B17<1,0,OFFSET(C41,-Inputs!B17,0)*(1-$B$5)^Inputs!B17) -> 33.849627 | E41: =IF(D41>0,F41/D41,0) -> 3066.3459 | F41: =F40*(1-$B$5)*(1+$B$6)+IF(A41-Inputs!B17<1,0,OFFSET(C41,-Inputs!B17,0)*(1-$B$5)^Inputs!B17)*$B$3 -> 103794.67 | G41: =F41*$B$4 -> 54492.199 | H41: =$B$9*B41*$B$7 -> 350 | I41: =$B$8 -> 17000 | J41: =G41-H41-I41 -> 37142.199 | K41: =K40+J41 -> 264679.97 | L41: =MIN(J41:J51) -> 37142.199
A42: 27 | B42: =IF(Inputs!B22=0,1,1/(1+EXP(-Inputs!B22*(A42-Inputs!B21)))) -> 1 | C42: =IF(A42-Inputs!B23<1,0,$B$9*IF(Inputs!B22=0,1,1/(1+EXP(-Inputs!B22*(A42-Inputs!B23-Inputs!B21))))) -> 2 | D42: =D41*(1-$B$5)+IF(A42-Inputs!B17<1,0,OFFSET(C42,-Inputs!B17,0)*(1-$B$5)^Inputs!B17) -> 34.834138 | E42: =IF(D42>0,F42/D42,0) -> 3078.5213 | F42: =F41*(1-$B$5)*(1+$B$6)+IF(A42-Inputs!B17<1,0,OFFSET(C42,-Inputs!B17,0)*(1-$B$5)^Inputs!B17)*$B$3 -> 107237.63 | G42: =F42*$B$4 -> 56299.758 | H42: =$B$9*B42*$B$7 -> 350 | I42: =$B$8 -> 17000 | J42: =G42-H42-I42 -> 38949.758 | K42: =K41+J42 -> 303629.73 | L42: =MIN(J42:J51) -> 38949.758
A43: 28 | B43: =IF(Inputs!B22=0,1,1/(1+EXP(-Inputs!B22*(A43-Inputs!B21)))) -> 1 | C43: =IF(A43-Inputs!B23<1,0,$B$9*IF(Inputs!B22=0,1,1/(1+EXP(-Inputs!B22*(A43-Inputs!B23-Inputs!B21))))) -> 2 | D43: =D42*(1-$B$5)+IF(A43-Inputs!B17<1,0,OFFSET(C43,-Inputs!B17,0)*(1-$B$5)^Inputs!B17) -> 35.789114 | E43: =IF(D43>0,F43/D43,0) -> 3090.6244 | F43: =F42*(1-$B$5)*(1+$B$6)+IF(A43-Inputs!B17<1,0,OFFSET(C43,-Inputs!B17,0)*(1-$B$5)^Inputs!B17)*$B$3 -> 110610.71 | G43: =F43*$B$4 -> 58070.623 | H43: =$B$9*B43*$B$7 -> 350 | I43: =$B$8 -> 17000 | J43: =G43-H43-I43 -> 40720.623 | K43: =K42+J43 -> 344350.35 | L43: =MIN(J43:J51) -> 40720.623
...

Sheet Pessimistic
A1: Pessimistic case
A3: Revenue per customer-month (ARPU₀) | B3: =Inputs!D5 -> 1850
A4: Gross margin | B4: =Inputs!D6 -> 0.4
A5: Monthly churn | B5: =Inputs!E7 -> 0.042
A6: Monthly expansion | B6: =Inputs!D8 -> 0
A7: Blended CAC | B7: =Inputs!E11 -> 300
A8: Fixed burn / month | B8: =Inputs!B14*Inputs!E10+Inputs!B15 -> 24000
A9: New customers / month at full capacity | B9: =Inputs!D9 -> 1
A10: LTV (lifetime contribution, 60-mo cap) | B10: =B3*B4*(1-B5)^Inputs!B17*IF(ABS(1-(1-B5)*(1+B6))<0.000001,MAX(0,60-Inputs!B17),(1-((1-B5)*(1+B6))^MAX(0,60-Inputs!B17))/(1-(1-B5)*(1+B6))) -> 16276.552
A11: LTV / CAC (cash) | B11: =IF(B7>0,B10/B7,"n/a") -> 54.255172
A12: Payback (months, cumulative; "none" = not within 60) | B12: =IF(B3*B4<=0,"none",IF(B7<=0,1+Inputs!B17,IF((1-B5)*(1+B6)<=0,IF(B7<=B3*B4*(1-B5)^Inputs!B17,1+Inputs!B17,"none"),IF(ABS(1-(1-B5)*(1+B6))<0.000001,IF(B7/(B3*B4*(1-B5)^Inputs!B17)<=60-Inputs!B17,ROUNDUP(B7/(B3*B4*(1-B5)^Inputs!B17),0)+Inputs!B17,"none"),IF(1-B7*(1-(1-B5)*(1+B6))/(B3*B4*(1-B5)^Inputs!B17)<=0,"none",IF(ROUNDUP(LN(1-B7*(1-(1-B5)*(1+B6))/(B3*B4*(1-B5)^Inputs!B17))/LN((1-B5)*(1+B6)),0)<=60-Inputs!B17,ROUNDUP(LN(1-B7*(1-(1-B5)*(1+B6))/(B3*B4*(1-B5)^Inputs!B17))/LN((1-B5)*(1+B6)),0)+Inputs!B17,"none")))))) -> 1
A15: Month | B15: Ramp | C15: New customers (arrivals) | D15: Paying customers | E15: ARPU (derived) | F15: Revenue | G15: Gross profit | H15: Acquisition spend | I15: Fixed burn | J15: Net cash flow | K15: Cumulative cash | L15: Lowest net from here on
A16: 1 | B16: =IF(Inputs!B22=0,1,1/(1+EXP(-Inputs!B22*(A16-Inputs!B21)))) -> 0.26894142 | C16: =IF(A16-Inputs!B23<1,0,$B$9*IF(Inputs!B22=0,1,1/(1+EXP(-Inputs!B22*(A16-Inputs!B23-Inputs!B21))))) -> 0 | D16: =Inputs!B19*(1-$B$5)+IF(A16-Inputs!B17<1,0,OFFSET(C16,-Inputs!B17,0)*(1-$B$5)^Inputs!B17) -> 0 | E16: =IF(D16>0,F16/D16,0) -> 0 | F16: =Inputs!B20*(1-$B$5)*(1+$B$6)+IF(A16-Inputs!B17<1,0,OFFSET(C16,-Inputs!B17,0)*(1-$B$5)^Inputs!B17)*$B$3 -> 0 | G16: =F16*$B$4 -> 0 | H16: =$B$9*B16*$B$7 -> 80.682426 | I16: =$B$8 -> 24000 | J16: =G16-H16-I16 -> -24080.682 | K16: =J16-Inputs!B16 -> -24080.682 | L16: =MIN(J16:J51) -> -24080.682
A17: 2 | B17: =IF(Inputs!B22=0,1,1/(1+EXP(-Inputs!B22*(A17-Inputs!B21)))) -> 0.5 | C17: =IF(A17-Inputs!B23<1,0,$B$9*IF(Inputs!B22=0,1,1/(1+EXP(-Inputs!B22*(A17-Inputs!B23-Inputs!B21))))) -> 0.26894142 | D17: =D16*(1-$B$5)+IF(A17-Inputs!B17<1,0,OFFSET(C17,-Inputs!B17,0)*(1-$B$5)^Inputs!B17) -> 0.26894142 | E17: =IF(D17>0,F17/D17,0) -> 1850 | F17: =F16*(1-$B$5)*(1+$B$6)+IF(A17-Inputs!B17<1,0,OFFSET(C17,-Inputs!B17,0)*(1-$B$5)^Inputs!B17)*$B$3 -> 497.54163 | G17: =F17*$B$4 -> 199.01665 | H17: =$B$9*B17*$B$7 -> 150 | I17: =$B$8 -> 24000 | J17: =G17-H17-I17 -> -23950.983 | K17: =K16+J17 -> -48031.666 | L17: =MIN(J17:J51) -> -23950.983
A18: 3 | B18: =IF(Inputs!B22=0,1,1/(1+EXP(-Inputs!B22*(A18-Inputs!B21)))) -> 0.73105858 | C18: =IF(A18-Inputs!B23<1,0,$B$9*IF(Inputs!B22=0,1,1/(1+EXP(-Inputs!B22*(A18-Inputs!B23-Inputs!B21))))) -> 0.5 | D18: =D17*(1-$B$5)+IF(A18-Inputs!B17<1,0,OFFSET(C18,-Inputs!B17,0)*(1-$B$5)^Inputs!B17) -> 0.75764588 | E18: =IF(D18>0,F18/D18,0) -> 1850 | F18: =F17*(1-$B$5)*(1+$B$6)+IF(A18-Inputs!B17<1,0,OFFSET(C18,-Inputs!B17,0)*(1-$B$5)^Inputs!B17)*$B$3 -> 1401.6449 | G18: =F18*$B$4 -> 560.65795 | H18: =$B$9*B18*$B$7 -> 219.31757 | I18: =$B$8 -> 24000 | J18: =G18-H18-I18 -> -23658.66 | K18: =K17+J18 -> -71690.325 | L18: =MIN(J18:J51) -> -23658.66
A19: 4 | B19: =IF(Inputs!B22=0,1,1/(1+EXP(-Inputs!B22*(A19-Inputs!B21)))) -> 0.88079708 | C19: =IF(A19-Inputs!B23<1,0,$B$9*IF(Inputs!B22=0,1,1/(1+EXP(-Inputs!B22*(A19-Inputs!B23-Inputs!B21))))) -> 0.73105858 | D19: =D18*(1-$B$5)+IF(A19-Inputs!B17<1,0,OFFSET(C19,-Inputs!B17,0)*(1-$B$5)^Inputs!B17) -> 1.4568833 | E19: =IF(D19>0,F19/D19,0) -> 1850 | F19: =F18*(1-$B$5)*(1+$B$6)+IF(A19-Inputs!B17<1,0,OFFSET(C19,-Inputs!B17,0)*(1-$B$5)^Inputs!B17)*$B$3 -> 2695.2342 | G19: =F19*$B$4 -> 1078.0937 | H19: =$B$9*B19*$B$7 -> 264.23912 | I19: =$B$8 -> 24000 | J19: =G19-H19-I19 -> -23186.145 | K19: =K18+J19 -> -94876.471 | L19: =MIN(J19:J51) -> -23186.145
A20: 5 | B20: =IF(Inputs!B22=0,1,1/(1+EXP(-Inputs!B22*(A20-Inputs!B21)))) -> 0.95257413 | C20: =IF(A20-Inputs!B23<1,0,$B$9*IF(Inputs!B22=0,1,1/(1+EXP(-Inputs!B22*(A20-Inputs!B23-Inputs!B21))))) -> 0.88079708 | D20: =D19*(1-$B$5)+IF(A20-Inputs!B17<1,0,OFFSET(C20,-Inputs!B17,0)*(1-$B$5)^Inputs!B17) -> 2.2764913 | E20: =IF(D20>0,F20/D20,0) -> 1850 | F20: =F19*(1-$B$5)*(1+$B$6)+IF(A20-Inputs!B17<1,0,OFFSET(C20,-Inputs!B17,0)*(1-$B$5)^Inputs!B17)*$B$3 -> 4211.5089 | G20: =F20*$B$4 -> 1684.6036 | H20: =$B$9*B20*$B$7 -> 285.77224 | I20: =$B$8 -> 24000 | J20: =G20-H20-I20 -> -22601.169 | K20: =K19+J20 -> -117477.64 | L20: =MIN(J20:J51) -> -22601.169
A21: 6 | B21: =IF(Inputs!B22=0,1,1/(1+EXP(-Inputs!B22*(A21-Inputs!B21)))) -> 0.98201379 | C21: =IF(A21-Inputs!B23<1,0,$B$9*IF(Inputs!B22=0,1,1/(1+EXP(-Inputs!B22*(A21-Inputs!B23-Inputs!B21))))) -> 0.95257413 | D21: =D20*(1-$B$5)+IF(A21-Inputs!B17<1,0,OFFSET(C21,-Inputs!B17,0)*(1-$B$5)^Inputs!B17) -> 3.1334528 | E21: =IF(D21>0,F21/D21,0) -> 1850 | F21: =F20*(1-$B$5)*(1+$B$6)+IF(A21-Inputs!B17<1,0,OFFSET(C21,-Inputs!B17,0)*(1-$B$5)^Inputs!B17)*$B$3 -> 5796.8877 | G21: =F21*$B$4 -> 2318.7551 | H21: =$B$9*B21*$B$7 -> 294.60414 | I21: =$B$8 -> 24000 | J21: =G21-H21-I21 -> -21975.849 | K21: =K20+J21 -> -139453.49 | L21: =MIN(J21:J51) -> -21975.849
A22: 7 | B22: =IF(Inputs!B22=0,1,1/(1+EXP(-Inputs!B22*(A22-Inputs!B21)))) -> 0.99330715 | C22: =IF(A22-Inputs!B23<1,0,$B$9*IF(Inputs!B22=0,1,1/(1+EXP(-Inputs!B22*(A22-Inputs!B23-Inputs!B21))))) -> 0.98201379 | D22: =D21*(1-$B$5)+IF(A22-Inputs!B17<1,0,OFFSET(C22,-Inputs!B17,0)*(1-$B$5)^Inputs!B17) -> 3.9838616 | E22: =IF(D22>0,F22/D22,0) -> 1850 | F22: =F21*(1-$B$5)*(1+$B$6)+IF(A22-Inputs!B17<1,0,OFFSET(C22,-Inputs!B17,0)*(1-$B$5)^Inputs!B17)*$B$3 -> 7370.1439 | G22: =F22*$B$4 -> 2948.0576 | H22: =$B$9*B22*$B$7 -> 297.99214 | I22: =$B$8 -> 24000 | J22: =G22-H22-I22 -> -21349.935 | K22: =K21+J22 -> -160803.42 | L22: =MIN(J22:J51) -> -21349.935
A23: 8 | B23: =IF(Inputs!B22=0,1,1/(1+EXP(-Inputs!B22*(A23-Inputs!B21)))) -> 0.99752738 | C23: =IF(A23-Inputs!B23<1,0,$B$9*IF(Inputs!B22=0,1,1/(1+EXP(-Inputs!B22*(A23-Inputs!B23-Inputs!B21))))) -> 0.99330715 | D23: =D22*(1-$B$5)+IF(A23-Inputs!B17<1,0,OFFSET(C23,-Inputs!B17,0)*(1-$B$5)^Inputs!B17) -> 4.8098465 | E23: =IF(D23>0,F23/D23,0) -> 1850 | F23: =F22*(1-$B$5)*(1+$B$6)+IF(A23-Inputs!B17<1,0,OFFSET(C23,-Inputs!B17,0)*(1-$B$5)^Inputs!B17)*$B$3 -> 8898.2161 | G23: =F23*$B$4 -> 3559.2864 | H23: =$B$9*B23*$B$7 -> 299.25821 | I23: =$B$8 -> 24000 | J23: =G23-H23-I23 -> -20739.972 | K23: =K22+J23 -> -181543.39 | L23: =MIN(J23:J51) -> -20739.972
A24: 9 | B24: =IF(Inputs!B22=0,1,1/(1+EXP(-Inputs!B22*(A24-Inputs!B21)))) -> 0.99908895 | C24: =IF(A24-Inputs!B23<1,0,$B$9*IF(Inputs!B22=0,1,1/(1+EXP(-Inputs!B22*(A24-Inputs!B23-Inputs!B21))))) -> 0.99752738 | D24: =D23*(1-$B$5)+IF(A24-Inputs!B17<1,0,OFFSET(C24,-Inputs!B17,0)*(1-$B$5)^Inputs!B17) -> 5.6053604 | E24: =IF(D24>0,F24/D24,0) -> 1850 | F24: =F23*(1-$B$5)*(1+$B$6)+IF(A24-Inputs!B17<1,0,OFFSET(C24,-Inputs!B17,0)*(1-$B$5)^Inputs!B17)*$B$3 -> 10369.917 | G24: =F24*$B$4 -> 4147.9667 | H24: =$B$9*B24*$B$7 -> 299.72668 | I24: =$B$8 -> 24000 | J24: =G24-H24-I24 -> -20151.76 | K24: =K23+J24 -> -201695.15 | L24: =MIN(J24:J51) -> -20151.76
A25: 10 | B25: =IF(Inputs!B22=0,1,1/(1+EXP(-Inputs!B22*(A25-Inputs!B21)))) -> 0.99966465 | C25: =IF(A25-Inputs!B23<1,0,$B$9*IF(Inputs!B22=0,1,1/(1+EXP(-Inputs!B22*(A25-Inputs!B23-Inputs!B21))))) -> 0.99908895 | D25: =D24*(1-$B$5)+IF(A25-Inputs!B17<1,0,OFFSET(C25,-Inputs!B17,0)*(1-$B$5)^Inputs!B17) -> 6.3690242 | E25: =IF(D25>0,F25/D25,0) -> 1850 | F25: =F24*(1-$B$5)*(1+$B$6)+IF(A25-Inputs!B17<1,0,OFFSET(C25,-Inputs!B17,0)*(1-$B$5)^Inputs!B17)*$B$3 -> 11782.695 | G25: =F25*$B$4 -> 4713.0779 | H25: =$B$9*B25*$B$7 -> 299.89939 | I25: =$B$8 -> 24000 | J25: =G25-H25-I25 -> -19586.822 | K25: =K24+J25 -> -221281.98 | L25: =MIN(J25:J51) -> -19586.822
A26: 11 | B26: =IF(Inputs!B22=0,1,1/(1+EXP(-Inputs!B22*(A26-Inputs!B21)))) -> 0.99987661 | C26: =IF(A26-Inputs!B23<1,0,$B$9*IF(Inputs!B22=0,1,1/(1+EXP(-Inputs!B22*(A26-Inputs!B23-Inputs!B21))))) -> 0.99966465 | D26: =D25*(1-$B$5)+IF(A26-Inputs!B17<1,0,OFFSET(C26,-Inputs!B17,0)*(1-$B$5)^Inputs!B17) -> 7.1011898 | E26: =IF(D26>0,F26/D26,0) -> 1850 | F26: =F25*(1-$B$5)*(1+$B$6)+IF(A26-Inputs!B17<1,0,OFFSET(C26,-Inputs!B17,0)*(1-$B$5)^Inputs!B17)*$B$3 -> 13137.201 | G26: =F26*$B$4 -> 5254.8805 | H26: =$B$9*B26*$B$7 -> 299.96298 | I26: =$B$8 -> 24000 | J26: =G26-H26-I26 -> -19045.083 | K26: =K25+J26 -> -240327.06 | L26: =MIN(J26:J51) -> -19045.083
